Workbook

Sheet Forecast
B1: Forecasting Assumptions | D1: 2020 | E1: 2025 | F1: 2030 | G1: 2035 | H1: 2040 | I1: 2045 | J1: 2050 | L1: Assumptions to be considered
A3: Assumptions
A5: Statement of Financial Position
A6: Opening cash and cash equivalents | D6: 4116
A7: Assets not elsewhere classified | D7: =D12-SUM(D50,D8:D9) -> 16685
A8: Property, plant and equipment | D8: 10558
A9: Goodwill and intangible assets | D9: =18942+15999 -> 34941
A10: Non-current liabilities (debt) | B10: Fixed debt to EBITDA ratio | D10: 29412 | E10: =$D10/$D18 -> 2.690204 | F10: =$D10/$D18 -> 2.690204 | G10: =$D10/$D18 -> 2.690204 | H10: =$D10/$D18 -> 2.690204 | I10: =$D10/$D18 -> 2.690204 | J10: =$D10/$D18 -> 2.690204
A11: Shareholders' equity (incl. non-controlling interests) | D11: 17655
A12: Total Balance Sheet | D12: 67659
A14: Income Statement
A15: Revenue | B15: YOY %-change from IAM | D15: 50724 | E15: =(IAM!F15/IAM!E15)^(1/5)-1 -> 0.019831963 | F15: =(IAM!G15/IAM!F15)^(1/5)-1 -> 0.019629726 | G15: =(IAM!H15/IAM!G15)^(1/5)-1 -> 0.016281198 | H15: =(IAM!I15/IAM!H15)^(1/5)-1 -> 0.017078976 | I15: =(IAM!J15/IAM!I15)^(1/5)-1 -> 0.017092973 | J15: =(IAM!K15/IAM!J15)^(1/5)-1 -> 0.015841518
A16: Cost of sales | B16: YOY %-change from IAM | D16: =28684/D15 -> 0.56549168 | E16: =(IAM!F17/IAM!E17)^(1/5)-1 -> 0.019265097 | F16: =(IAM!G17/IAM!F17)^(1/5)-1 -> 0.019227088 | G16: =(IAM!H17/IAM!G17)^(1/5)-1 -> 0.014194481 | H16: =(IAM!I17/IAM!H17)^(1/5)-1 -> 0.015506627 | I16: =(IAM!J17/IAM!I17)^(1/5)-1 -> 0.015677706 | J16: =(IAM!K17/IAM!J17)^(1/5)-1 -> 0.015021935
A17: Operating expenses (Costs of labour) | B17: YOY %-change from IAM | D17: =(1-$D16)-D18/D15 -> 0.21896932 | E17: =(IAM!F20/IAM!E20)^(1/5)-1 -> 0.019238341 | F17: =(IAM!G20/IAM!F20)^(1/5)-1 -> 0.018026024 | G17: =(IAM!H20/IAM!G20)^(1/5)-1 -> 0.013284343 | H17: =(IAM!I20/IAM!H20)^(1/5)-1 -> 0.013156824 | I17: =(IAM!J20/IAM!I20)^(1/5)-1 -> 0.01239681 | J17: =(IAM!K20/IAM!J20)^(1/5)-1 -> 0.010256282
A18: EBITDA (Cash flow from operating activities) | B18: YOY %-change from IAM | D18: 10933 | E18: =(IAM!F21/IAM!E21)^(1/5)-1 -> 0.022560111 | F18: =(IAM!G21/IAM!F21)^(1/5)-1 -> 0.022634755 | G18: =(IAM!H21/IAM!G21)^(1/5)-1 -> 0.026537376 | H18: =(IAM!I21/IAM!H21)^(1/5)-1 -> 0.025765215 | I18: =(IAM!J21/IAM!I21)^(1/5)-1 -> 0.025417199 | J18: =(IAM!K21/IAM!J21)^(1/5)-1 -> 0.022539453
A19: Depreciation rate (incl. amortisation) | B19: Constant rate | D19: =2018/D8 -> 0.19113468 | E19: =$D19 -> 0.19113468 | F19: =$D19 -> 0.19113468 | G19: =$D19 -> 0.19113468 | H19: =$D19 -> 0.19113468 | I19: =$D19 -> 0.19113468 | J19: =$D19 -> 0.19113468
A20: Underlying effective debt interest rate | B20: Constant rate | D20: =624/D10 -> 0.02121583 | E20: =$D20 -> 0.02121583 | F20: =$D20 -> 0.02121583 | G20: =$D20 -> 0.02121583 | H20: =$D20 -> 0.02121583 | I20: =$D20 -> 0.02121583 | J20: =$D20 -> 0.02121583
A21: Underlying effective tax rate on EBT | B21: Constant rate | D21: =1923/SUM(D37,D39:D41) -> 0.24049525 | E21: =$D21 -> 0.24049525 | F21: =$D21 -> 0.24049525 | G21: =$D21 -> 0.24049525 | H21: =$D21 -> 0.24049525 | I21: =$D21 -> 0.24049525 | J21: =$D21 -> 0.24049525
A22: Capital expenditure (on non-financial assets) | B22: Fixed Capex to revenue ratio | D22: =-Actual!$K51/$D15 -> 0.018373945 | E22: =-Actual!$K51/$D15 -> 0.018373945 | F22: =-Actual!$K51/$D15 -> 0.018373945 | G22: =-Actual!$K51/$D15 -> 0.018373945 | H22: =-Actual!$K51/$D15 -> 0.018373945 | I22: =-Actual!$K51/$D15 -> 0.018373945 | J22: =-Actual!$K51/$D15 -> 0.018373945 | L22: To be linked to Inv %-change from IAM
A23: Net change in debt | D23: =SUM(Actual!O45:O46) -> 0
A24: Net change in other liabilities | D24: =SUM(Actual!O44,Actual!O47) -> 1425
A25: Underlying effective dividend rate | D25: =4279/D11 -> 0.2423676 | E25: =D25 -> 0.2423676 | F25: =E25 -> 0.2423676 | G25: =F25 -> 0.2423676 | H25: =G25 -> 0.2423676 | I25: =H25 -> 0.2423676 | J25: =I25 -> 0.2423676
A26: Net change in equity | D26: =SUM(Actual!O51:O52) -> 0
A27: Net change in other equity equivalents | D27: =SUM(Actual!O50,Actual!O54:O55) -> 0
A30: Income Statement | O30: Balanced (2025) | P30: Unbalanced (2025)
A32: Revenue | B32: =B36 -> Share-adjusted YOY %-change from IAM | C32: =C36 -> 2 | D32: =D15 -> 50724 | E32: =E$37*D32*(1+E15)^5/(D32*(1+E15)^5+D33*(1+E16)^5+D36*(1+E17)^5) -> 56135.108 | F32: =F$37*E32*(1+F15)^5/(E32*(1+F15)^5+E33*(1+F16)^5+E36*(1+F17)^5) -> 61978.452 | G32: =G$37*F32*(1+G15)^5/(F32*(1+G15)^5+F33*(1+G16)^5+F36*(1+G17)^5) -> 67901.48 | H32: =H$37*G32*(1+H15)^5/(G32*(1+H15)^5+G33*(1+H16)^5+G36*(1+H17)^5) -> 74396.093 | I32: =I$37*H32*(1+I15)^5/(H32*(1+I15)^5+H33*(1+I16)^5+H36*(1+I17)^5) -> 81392.933 | J32: =J$37*I32*(1+J15)^5/(I32*(1+J15)^5+I33*(1+J16)^5+I36*(1+J17)^5) -> 88207.081 | N32: Share-(un)adjusted YOY %-change from IAM | O32: =O$37*D32*(1+E15)^5/(D32*(1+E15)^5+D33*(1+E16)^5+D36*(1+E17)^5) -> 56135.108 | P32: =D32*(1+E15)^5 -> 55957.279
A33: Cost of sales | B33: =B36 -> Share-adjusted YOY %-change from IAM | C33: =C36 -> 2 | D33: =-$D16*D$32 -> -28684 | E33: =E$37*D33*(1+E16)^5/(D32*(1+E15)^5+D33*(1+E16)^5+D36*(1+E17)^5) -> -31655.812 | F33: =F$37*E33*(1+F16)^5/(E32*(1+F15)^5+E33*(1+F16)^5+E36*(1+F17)^5) -> -34882.047 | G33: =G$37*F33*(1+G16)^5/(F32*(1+G15)^5+F33*(1+G16)^5+F36*(1+G17)^5) -> -37824.852 | H33: =H$37*G33*(1+H16)^5/(G32*(1+H15)^5+G33*(1+H16)^5+G36*(1+H17)^5) -> -41123.356 | I33: =I$37*H33*(1+I16)^5/(H32*(1+I15)^5+H33*(1+I16)^5+H36*(1+I17)^5) -> -44678.794 | J33: =J$37*I33*(1+J16)^5/(I32*(1+J15)^5+I33*(1+J16)^5+I36*(1+J17)^5) -> -48224.257 | N33: Share-(un)adjusted YOY %-change from IAM | O33: =O$37*D33*(1+E16)^5/(D32*(1+E15)^5+D33*(1+E16)^5+D36*(1+E17)^5) -> -31655.812 | P33: =D33*(1+E16)^5 -> -31555.53
A34: Total gross profit | D34: =SUM(D32:D33) -> 22040 | E34: =SUM(E32:E33) -> 24479.297 | F34: =SUM(F32:F33) -> 27096.406 | G34: =SUM(G32:G33) -> 30076.628 | H34: =SUM(H32:H33) -> 33272.737 | I34: =SUM(I32:I33) -> 36714.138 | J34: =SUM(J32:J33) -> 39982.824 | O34: =SUM(O32:O33) -> 24479.297 | P34: =SUM(P32:P33) -> 24401.749
A36: Operating expenses (Costs of labour) | B36: Share-adjusted YOY %-change from IAM | C36: 2 | D36: =-$D17*D$32 -> -11107 | E36: =E37*D36*(1+E17)^5/(D32*(1+E15)^5+D33*(1+E16)^5+D36*(1+E17)^5) -> -12256.134 | F36: =F37*E36*(1+F17)^5/(E32*(1+F15)^5+E33*(1+F16)^5+E36*(1+F17)^5) -> -13425.845 | G36: =G37*F36*(1+G17)^5/(F32*(1+G15)^5+F33*(1+G16)^5+F36*(1+G17)^5) -> -14493.302 | H36: =H37*G36*(1+H17)^5/(G32*(1+H15)^5+G33*(1+H16)^5+G36*(1+H17)^5) -> -15575.723 | I36: =I37*H36*(1+I17)^5/(H32*(1+I15)^5+H33*(1+I16)^5+H36*(1+I17)^5) -> -16650.81 | J36: =J37*I36*(1+J17)^5/(I32*(1+J15)^5+I33*(1+J16)^5+I36*(1+J17)^5) -> -17554.163 | N36: Share-adjusted YOY %-change from IAM | O36: =O37*D36*(1+E17)^5/(D32*(1+E15)^5+D33*(1+E16)^5+D36*(1+E17)^5) -> -12256.134 | P36: =D36*(1+E17)^5 -> -12217.308
A37: EBITDA (Cash flow from operating activities) | B37: YOY %-change from IAM | C37: 1 | D37: =SUM(D34,D36) -> 10933 | E37: =D37*(1+E18)^5 -> 12223.162 | F37: =E37*(1+F18)^5 -> 13670.561 | G37: =F37*(1+G18)^5 -> 15583.326 | H37: =G37*(1+H18)^5 -> 17697.014 | I37: =H37*(1+I18)^5 -> 20063.329 | J37: =I37*(1+J18)^5 -> 22428.661 | N37: YOY %-change from IAM (Total) | O37: =D37*(1+E18)^5 -> 12223.162 | P37: =SUM(P34,P36) -> 12184.441
A39: Depreciation, amortisation and impairment | B39: Geometric rate on net physical assets | C39: 3c | D39: =-D19*D52 -> -2018 | E39: =-E19*E52 -> -1859.6896 | F39: =-F19*F52 -> -1744.0107 | G39: =-G19*G52 -> -1664.3574 | H39: =-H19*H52 -> -1616.634 | I39: =-I19*I52 -> -1597.1978 | J39: =-J19*J52 -> -1600.971 | N39: EBITDA YOY %-change from IAM | O39: =D39*(1+E$18)^5 -> -2256.1366 | P39: =D39*(1+E$18)^5 -> -2256.1366
A40: Interest payments (linked to debt) | B40: =B20 -> Constant rate | C40: 4b | D40: =-D20*D56 -> -624 | E40: =-E20*E56 -> -697.63591 | F40: =-F20*F56 -> -780.24603 | G40: =-G20*G56 -> -889.41695 | H40: =-H20*H56 -> -1010.0555 | I40: =-I20*I56 -> -1145.1127 | J40: =-J20*J56 -> -1280.1138 | N40: EBITDA YOY %-change from IAM | O40: =D40*(1+E$18)^5 -> -697.63591 | P40: =D40*(1+E$18)^5 -> -697.63591
A41: Other income and balance sheet movements | B41: For base year reconciliation only | D41: =-(SUM(Actual!K31:K32,Actual!K36:K43)+D40) -> -295 | N41: EBITDA YOY %-change from IAM | O41: =D41*(1+E$18)^5 -> -329.81185 | P41: =D41*(1+E$18)^5 -> -329.81185
A42: Corporate tax (Capital income tax) | B42: =B21 -> Constant rate | C42: 5 | D42: =-D21*SUM(D37,D39:D41) -> -1923 | E42: =-E21*SUM(E37,E39:E41) -> -2324.5879 | F42: =-F21*SUM(F37,F39:F41) -> -2680.6331 | G42: =-G21*SUM(G37,G39:G41) -> -3133.5453 | H42: =-H21*SUM(H37,H39:H41) -> -3624.3414 | I42: =-I21*SUM(I37,I39:I41) -> -4165.6225 | J42: =-J21*SUM(J37,J39:J41) -> -4701.0992 | N42: EBITDA YOY %-change from IAM | O42: =D42*(1+E$18)^5 -> -2149.926 | P42: =D42*(1+E$18)^5 -> -2149.926
A43: Net income | B43: Closure - Income statement residual | D43: =SUM(D37,D39:D42) -> 6073 | E43: =SUM(E37,E39:E42) -> 7341.2491 | F43: =SUM(F37,F39:F42) -> 8465.6708 | G43: =SUM(G37,G39:G42) -> 9896.0065 | H43: =SUM(H37,H39:H42) -> 11445.983 | I43: =SUM(I37,I39:I42) -> 13155.396 | J43: =SUM(J37,J39:J42) -> 14846.477 | N43: EBITDA YOY %-change from IAM | O43: =D43*(1+E$18)^5 -> 6789.652 | P43: =D43*(1+E$18)^5 -> 6789.652
A45: Income statement check | D45: =SUM(D37,D39:D42)-D43 -> 0 | E45: =SUM(E37,E39:E42)-E43 -> 0 | F45: =SUM(F37,F39:F42)-F43 -> 0 | G45: =SUM(G37,G39:G42)-G43 -> 0 | H45: =SUM(H37,H39:H42)-H43 -> 0 | I45: =SUM(I37,I39:I42)-I43 -> 0 | J45: =SUM(J37,J39:J42)-J43 -> 0 | N45: Total | O45: =SUM(O37,O39:O42)-O43 -> 0 | P45: =SUM(P37,P39:P42)-P43 -> -38.721437
A48: Statement of Financial Position
A50: Cash and equivalents | B50: From cash flow calculation | D50: =D97 -> 5475 | E50: =E97 -> 12836.315 | F50: =F97 -> 21522.005 | G50: =G97 -> 32701.48 | H50: =H97 -> 45804.399 | I50: =I97 -> 61148.352 | J50: =J97 -> 78059.315
A51: Assets not elsewhere classified | B51: No change | D51: =D7 -> 16685 | E51: =D51 -> 16685 | F51: =E51 -> 16685 | G51: =F51 -> 16685 | H51: =G51 -> 16685 | I51: =H51 -> 16685 | J51: =I51 -> 16685
A52: Property, plant and equipment | B52: K(t) = [ I(t) + K(t-1) ] / [1 + δ] | C52: 3b | D52: =D8 -> 10558 | E52: =(D52-E77)/(1+E19) -> 9729.7338 | F52: =(E52-F77)/(1+F19) -> 9124.5118 | G52: =(F52-G77)/(1+G19) -> 8707.7725 | H52: =(G52-H77)/(1+H19) -> 8458.0882 | I52: =(H52-I77)/(1+I19) -> 8356.3997 | J52: =(I52-J77)/(1+J19) -> 8376.1408
...

Sheet Actual
A1: Income Statement | B1: Costco | C1: Unilever | E1: NOPAT and Its Reconciliation to Net Income | F1: Costco | G1: Unilever | I1: Consolidated Statements of Cash Flows | J1: Costco | K1: Unilever | M1: Free Cash Flow and Cash Flow to Investors | N1: Costco | O1: Unilever
A3: Merchandise sales | B3: 149351 | C3: 50724
A4: Membership fees | B4: 3352
A5: Revenues | B5: =SUM(B3:B4) -> 152703 | C5: =SUM(C3:C4) -> 50724
A7: Merchandise costs | B7: -132886 | C7: -28684
A8: Selling, general, and administrative | B8: -13502 | C8: =-12673-C9 -> -10655
A9: Depreciation | B9: -1492 | C9: -2018
A10: Remaining items | B10: -86 | C10: -1064
A11: Operating income/profit | B11: =SUM(B5:B10) -> 4737 | C11: =SUM(C5:C10) -> 8303 | E11: EBITA, unadjusted | F11: =B11 -> 4737 | G11: =C11 -> 8303
A13: Interest expense | B13: -150 | C13: =-9-728 -> -737 | E13: Operating lease interest | F13: 91
A14: Interest income | B14: 126 | C14: 232 | E14: EBITA, adjusted | F14: =SUM(F11:F13) -> 4828 | G14: =SUM(G11:G13) -> 8303
A15: Other income | B15: 52 | C15: =20+175+3 -> 198
A16: Earnings before taxes | B16: =SUM(B11:B15) -> 4765 | C16: =SUM(C11:C15) -> 7996 | E16: Operating cash taxes | F16: -1009 | G16: -1923
E17: NOPAT | F17: =SUM(F14:F16) -> 3819 | G17: =SUM(G14:G16) -> 6380 | M17: NOPAT | N17: =F17 -> 3819 | O17: =G17 -> 6380
M18: Depreciation | N18: =-B9 -> 1492 | O18: =-C9 -> 2018
E19: Taxes related to nonoperating accounts | F19: 15 | M19: Gross cash flow | N19: =SUM(N17:N18) -> 5311 | O19: =SUM(O17:O18) -> 8398
E20: Other nonoperating taxes | F20: 92
M21: Decrease (increase) in working capital | N21: 449 | O21: 680
E22: Interest expense | F22: =B13 -> -150 | G22: =C13 -> -737 | M22: Other cash movements from operations | O22: =SUM(K30,K37:K38,K43,K46) -> -20
E23: Operating lease interest | F23: =-F13 -> -91 | G23: =-G13 -> 0 | M23: Net cash provided by operating activities | N23: =SUM(N19:N22) -> 5760 | O23: =SUM(O19:O22) -> 9058
E24: Interest income | F24: =B14 -> 126 | G24: =C14 -> 232
E25: Other income | F25: =B15 -> 52 | G25: =C15 -> 198 | M25: Less: Capital expenditures | N25: =J51 -> -2998 | O25: =K51 -> -932
E26: Adjusted net income | F26: =SUM(F17:F25) -> 3863 | G26: =SUM(G17:G25) -> 6073 | M26: Decrease (increase) in capitalized operating leases | N26: 86
M27: Decrease (increase) in other assets, net of liabilities | N27: -173
A28: Provision for income taxes | B28: =SUM(F16,F19:F20,F28) -> -1061 | C28: =SUM(G16,G19:G20,G28) -> -1923 | E28: Operating taxes deferred | F28: -159 | M28: Other cash movements in invested capital | O28: =K54+K67 -> -455
A29: Net income, consolidated | B29: =SUM(B16:B28) -> 3704 | C29: =SUM(C16:C28) -> 6073 | E29: Net income, consolidated | F29: =SUM(F26:F28) -> 3704 | G29: =SUM(G26:G28) -> 6073 | I29: Net income/profit | J29: =F29 -> 3704 | K29: =G29 -> 6073 | M29: Free cash flow | N29: =SUM(N23:N28) -> 2675 | O29: =SUM(O23:O28) -> 7671
I30: Taxation | K30: 1923
A31: Net income, noncontrolling interests | B31: -45 | I31: Other income | K31: =-C15 -> -198 | M31: Interest income | N31: =F24 -> 126 | O31: =G24 -> 232
A32: Net income | B32: =SUM(B29:B31) -> 3659 | C32: =SUM(C29:C31) -> 6073 | I32: Net finance costs | K32: =-SUM(C13:C14) -> 505 | M32: Other income | N32: =F25 -> 52 | O32: =G25 -> 198
I33: Operating income/profit | J33: =SUM(J29:J32) -> 3704 | K33: =SUM(K29:K32) -> 8303 | M33: Taxes related to nonoperating accounts | N33: =F19 -> 15 | O33: =G19 -> 0
M34: Other nonoperating taxes | N34: =F20 -> 92 | O34: =G20 -> 0
I35: Depreciation and amortization | J35: =-B9 -> 1492 | K35: =-C9 -> 2018 | M35: Decrease (increase) in excess cash | N35: -1962 | O35: -1773
I36: Non-cash lease expense | M36: Decrease (increase) in tax credit carryforward | N36: -65
I37: Stock-based compensation | J37: 595 | K37: 108 | M37: Unexplained foreign-currency translation | N37: 60
I38: Other non-cash operating activities, net | J38: 9 | K38: -1 | M38: Other nonoperating cash flows
I39: Deferred income taxes | J39: 147 | M39: Cash flow to investors | N39: =SUM(N29:N37) -> 993 | O39: =SUM(O29:O37) -> 6328
I40: Changes in operating assets and liabilities
I41: Merchandise inventories | J41: -536 | K41: -587 | M41: Reconciliation of cash flow to investors
I42: Accounts payable | J42: 322 | K42: =1125+142 -> 1267
I43: Other operating assets and liabilities, net | J43: 623 | K43: =-182-53+60 -> -175 | M43: Interest expense | N43: =-F22 -> 150 | O43: =-K67 -> 624
...

Sheet IAM
A1: (€ million, 2020) | C1: World | D1: The Americas | E1: Europe | F1: Asia/AMET/RUB
A3: Total revenue | C3: =SUM(C4:C6) -> 50724 | D3: 16080 | E3: 11204 | F3: 23440
A4: Beauty & Personal Care (33) | C4: 21124 | D4: =$C4/$C$3*D$3 -> 6696.5129 | E4: =$C4/$C$3*E$3 -> 4665.9036 | F4: =$C4/$C$3*F$3 -> 9761.5835
A5: Home Care (31) | C5: 10460 | D5: =$C5/$C$3*D$3 -> 3315.9215 | E5: =$C5/$C$3*E$3 -> 2310.4219 | F5: =$C5/$C$3*F$3 -> 4833.6567
A6: Foods & Refreshment (22, 25) | C6: 19140 | D6: =$C6/$C$3*D$3 -> 6067.5656 | E6: =$C6/$C$3*E$3 -> 4227.6745 | F6: =$C6/$C$3*F$3 -> 8844.7599
A9: Current Aggregation (Version 3.7) | E9: Based on Updated Coefficients | M9: Based on Qty/Price YOY%
A11: Sector | B11: Chemicals | C11: Firm | E11: Chemicals | F11: Chemicals | G11: Chemicals | H11: Chemicals | I11: Chemicals | J11: Chemicals | K11: Chemicals | M11: Chemicals | N11: Chemicals
B12: (USA, 33) | C12: =C15/B15 -> 0.083092247 | E12: (USA, 33) | F12: (USA, 33) | G12: (USA, 33) | H12: (USA, 33) | I12: (USA, 33) | J12: (USA, 33) | K12: (USA, 33) | M12: (USA, 33) | N12: (USA, 33)
A13: Share | B13: 2014 | C13: 2020 | E13: 2020 | F13: 2025 | G13: 2030 | H13: 2035 | I13: 2040 | J13: 2045 | K13: 2050 | M13: 2020 | N13: 2025
A15: Revenue | B15: ='US SAM'!DF186 -> 610454.06 | C15: =C3 -> 50724 | E15: 621549.69 | F15: 685676 | G15: 755668.62 | H15: 819220.56 | I15: 891608.56 | J15: 970459.69 | K15: 1049801.8 | M15: {=B15*PRODUCT(1+'3.7-1_O20'!I2:N3/100)-1} -> 621263.86 | N15: {=M15*PRODUCT(1+'3.7-1_O20'!O2:S3/100)-1} -> 685137.41
A16: Non-product indirect tax | B16: ='US SAM'!GD403 -> 3975.5 | C16: =C$12*B16 -> 330.33323 | E16: 4047.8125 | F16: 4465.25 | G16: 4920.8125 | H16: 5334.5 | I16: 5805.9375 | J16: 6319.125 | K16: 6836 | M16: =B16+SUM('3.7-1_O20'!I8:N8) -> 4425.3839 | N16: =M16+SUM('3.7-1_O20'!O8:S8) -> 5062.7905
A17: Intermediate demand | B17: =SUM('US SAM'!GD2:GD153,'US SAM'!GD237:GD388) -> 418986.24 | C17: =C$12*B17 -> 34814.508 | E17: 409408.68 | F17: 450394.22 | G17: 495390.41 | H17: 531561.86 | I17: 574073.66 | J17: 620507.76 | K17: 668535.32 | M17: {=B17*PRODUCT(1+'3.7-1_O20'!I4:N5/100)-1} -> 428195.57 | N17: {=M17*PRODUCT(1+'3.7-1_O20'!O4:S5/100)-1} -> 473566.26
A18: Total gross profit | B18: =B15-SUM(B16:B17) -> 187492.32 | C18: =C15-SUM(C16:C17) -> 15579.159 | E18: =E15-SUM(E16:E17) -> 208093.2 | F18: =F15-SUM(F16:F17) -> 230816.53 | G18: =G15-SUM(G16:G17) -> 255357.4 | H18: =H15-SUM(H16:H17) -> 282324.21 | I18: =I15-SUM(I16:I17) -> 311728.97 | J18: =J15-SUM(J16:J17) -> 343632.8 | K18: =K15-SUM(K16:K17) -> 374430.43 | M18: =M15-SUM(M16:M17) -> 188642.91 | N18: =N15-SUM(N16:N17) -> 206508.36
A20: Costs of labour (wages, salaries) | B20: =SUM('US SAM'!GD231:GD232,'US SAM'!GD390:GD391) -> 100827.48 | C20: =C$12*B20 -> 8377.9823 | E20: 101597.08 | F20: 111753.2 | G20: 122195.27 | H20: 130530.21 | I20: 139345.97 | J20: 148200.02 | K20: 155957.42 | M20: {=B20*PRODUCT(1+'3.7-1_O20'!I6:N7/100)-1} -> 101582.51 | N20: {=M20*PRODUCT(1+'3.7-1_O20'!O6:S7/100)-1} -> 111744.69
A21: EBITDA | B21: =B18-B20 -> 86664.84 | C21: =C18-C20 -> 7201.1764 | E21: =E18-E20 -> 106496.12 | F21: =F18-F20 -> 119063.33 | G21: =G18-G20 -> 133162.14 | H21: =H18-H20 -> 151793.99 | I21: =I18-I20 -> 172383 | J21: =J18-J20 -> 195432.78 | K21: =K18-K20 -> 218473.01 | M21: =M18-M20 -> 87060.397 | N21: =N18-N20 -> 94763.664
A23: Return to capital (dep, int & div) | B23: ='US SAM'!GD233 -> 83912.016 | C23: =C$12*B23 -> 6972.438 | E23: 103113.39 | F23: 115281.3 | G23: 128932.03 | H23: 146972.03 | I23: 166907.16 | J23: 189224.73 | K23: 211533.09 | M23: {=B23*PRODUCT(1+'3.7-1_O20'!I9:N10/100)-1} -> 103078.2 | N23: {=M23*PRODUCT(1+'3.7-1_O20'!O9:S10/100)-1} -> 115171.59
A24: Capital income tax | B24: ='US SAM'!GD392 -> 2752.7734 | C24: =C$12*B24 -> 228.73413 | E24: =106496.0703125-E23 -> 3382.6797 | F24: =119063.15625-F23 -> 3781.8516 | G24: =133161.734375-G23 -> 4229.7031 | H24: =151793.515625-H23 -> 4821.4844 | I24: =172382.59375-I23 -> 5475.4375 | J24: =195432.3125-J23 -> 6207.5781 | K24: =218472.55-K23 -> 6939.4562 | M24: =B24+SUM('3.7-1_O20'!I11:N11) -> 3683.5558 | N24: =M24+SUM('3.7-1_O20'!O11:S11) -> 4267.7315
A25: Pure profits | B25: =B21-SUM(B23:B24) -> 0.051221 | C25: =C21-SUM(C23:C24) -> 0.004256068 | E25: =E21-SUM(E23:E24) -> 0.0479955 | F25: =F21-SUM(F23:F24) -> 0.17085 | G25: =G21-SUM(G23:G24) -> 0.402999 | H25: =H21-SUM(H23:H24) -> 0.4788755 | I25: =I21-SUM(I23:I24) -> 0.403398 | J25: =J21-SUM(J23:J24) -> 0.470095 | K25: =K21-SUM(K23:K24) -> 0.455661 | M25: =M21-SUM(M23:M24) -> -19701.358 | N25: =N21-SUM(N23:N24) -> -24675.66
B28: Potential Aggregation
A30: Sector | B30: Dairy | C30: Other Food | D30: Pulp, Paper | E30: Chemicals | F30: Sectors | G30: Firm
B31: (mil, 22) | C31: (ofd, 25) | D31: (ppp, 31) | E31: (chm, 33) | F31: (22, 25, 31, 33)
A32: Share | B32: =C6/SUM($B$34:$C$34) -> 0.0051390898 | C32: =C6/SUM($B$34:$C$34) -> 0.0051390898 | D32: =C5/D34 -> 0.0058431028 | E32: =C4/E34 -> 0.004818213 | G32: =G34/F34 -> 0.0051242897
A34: Revenue | B34: ='World SAM'!CU175 -> 796859.97 | C34: ='World SAM'!CX178 -> 2927534.9 | D34: ='World SAM'!DD184 -> 1790144.8 | E34: ='World SAM'!DF186 -> 4384198.1 | F34: =SUM(B34:E34) -> 9898737.7 | G34: =SUMPRODUCT($B$32:$E$32,B34:E34) -> 50724
A35: Non-product indirect tax | B35: ='World SAM'!FS403 -> 4155.6584 | C35: ='World SAM'!FV403 -> 10476.311 | D35: ='World SAM'!GB403 -> 14434.41 | E35: ='World SAM'!GD403 -> 14506.023 | F35: =SUM(B35:E35) -> 43572.403 | G35: =SUMPRODUCT($B$32:$E$32,B35:E35) -> 229.42986
A36: Intermediate demand | B36: =SUM('World SAM'!FS2:'World SAM'!FS153,'World SAM'!FS237:'World SAM'!FS388) -> 620335.02 | C36: =SUM('World SAM'!FV2:'World SAM'!FV153,'World SAM'!FV237:'World SAM'!FV388) -> 2092735.3 | D36: =SUM('World SAM'!GB2:'World SAM'!GB153,'World SAM'!GB237:'World SAM'!GB388) -> 1170257.3 | E36: =SUM('World SAM'!GD2:'World SAM'!GD153,'World SAM'!GD237:'World SAM'!GD388) -> 3427180.4 | F36: =SUM(B36:E36) -> 7310507.9 | G36: =SUMPRODUCT($B$32:$E$32,B36:E36) -> 37293.53
A37: Total gross profit | B37: =B34-SUM(B35:B36) -> 172369.28 | C37: =C34-SUM(C35:C36) -> 824323.36 | D37: =D34-SUM(D35:D36) -> 605453.12 | E37: =E34-SUM(E35:E36) -> 942511.68 | F37: =F34-SUM(F35:F36) -> 2544657.4 | G37: =G34-SUM(G35:G36) -> 13201.04
A39: Costs of labour (wages, salaries) | B39: =SUM('World SAM'!FS231:FS232,'World SAM'!FS390:FS391) -> 83951.581 | C39: =SUM('World SAM'!FV231:FV232,'World SAM'!FV390:FV391) -> 416251.18 | D39: =SUM('World SAM'!GB231:GB232,'World SAM'!GB390:GB391) -> 351127.62 | E39: =SUM('World SAM'!GD231:GD232,'World SAM'!GD390:GD391) -> 355590.01 | F39: =SUM(B39:E39) -> 1206920.4 | G39: =SUMPRODUCT($B$32:$E$32,B39:E39) -> 6335.5701
A40: EBITDA | B40: =B37-B39 -> 88417.703 | C40: =C37-C39 -> 408072.17 | D40: =D37-D39 -> 254325.5 | E40: =E37-E39 -> 586921.66 | F40: =F37-F39 -> 1337737 | G40: =G37-G39 -> 6865.4697
A42: Return to capital (dep, int & div) | B42: ='World SAM'!FS233 -> 86428.504 | C42: ='World SAM'!FV233 -> 398049.03 | D42: ='World SAM'!GB233 -> 247647.14 | E42: ='World SAM'!GD233 -> 572448.35 | F42: =SUM(B42:E42) -> 1304573 | G42: =SUMPRODUCT($B$32:$E$32,B42:E42) -> 6694.9794
A43: Capital income tax | B43: ='World SAM'!FS392 -> 1989.175 | C43: ='World SAM'!FV392 -> 10023.217 | D43: ='World SAM'!GB392 -> 6678.3712 | E43: ='World SAM'!GD392 -> 14473.161 | F43: =SUM(B43:E43) -> 33163.924 | G43: =SUMPRODUCT($B$32:$E$32,B43:E43) -> 170.48994
A44: Pure profits | B44: =B40-SUM(B42:B43) -> 0.024548 | C44: =C40-SUM(C42:C43) -> -0.078083001 | D44: =D40-SUM(D42:D43) -> -0.015318 | E44: =E40-SUM(E42:E43) -> 0.152802 | F44: =F40-SUM(F42:F43) -> 0.083949003 | G44: =G40-SUM(G42:G43) -> 0.00037160676

Sheet 3.7-1_O20
A1: Variable | B1: Measure | C1: Unit | D1: Style | E1: Region | F1: Sector | G1: Commodity | H1: 2014 | I1: 2015 | J1: 2016 | K1: 2017 | L1: 2018 | M1: 2019 | N1: 2020 | O1: 2021 | P1: 2022 | Q1: 2023 | R1: 2024 | S1: 2025 | T1: 2026 | U1: 2027 | V1: 2028 | W1: 2029 | X1: 2030 | Y1: 2031 | Z1: 2032 | AA1: 2033 | AB1: 2034 | AC1: 2035 | AD1: 2036 | AE1: 2037 | AF1: 2038 | AG1: 2039 | AH1: 2040 | AI1: 2041 | AJ1: 2042 | AK1: 2043 | AL1: 2044 | AM1: 2045 | AN1: 2046 | AO1: 2047 | AP1: 2048 | AQ1: 2049 | AR1: 2050
A2: Output | B2: Quantity | C2: Mill$ | D2: YOY% | E2: US | F2: Chemicals | G2: _Macro | I2: -0.16822109 | J2: 2.3741691 | K2: 2.5660856 | L2: 2.6936049 | M2: 2.76545 | N2: 2.7889814 | O2: 3.2386124 | P2: 3.1698079 | Q2: 3.0827944 | R2: 2.985213 | S2: 2.8826036 | T2: 2.7805359 | U2: 2.688 | V2: 2.6058736 | W2: 2.5329678 | X2: 2.4682093 | Y2: 2.0274742 | Z2: 1.9976623 | AA2: 1.9813111 | AB2: 1.9777035 | AC2: 1.9857428 | AD2: 2.0021255 | AE2: 2.0190053 | AF2: 2.0339119 | AG2: 2.0463281 | AH2: 2.0557845 | AI2: 2.0275865 | AJ2: 2.0293005 | AK2: 2.0270565 | AL2: 2.0220995 | AM2: 2.0153718 | AN2: 2.0069458 | AO2: 1.9942038 | AP2: 1.9767956 | AQ2: 1.9550815 | AR2: 1.9293698
A3: Output | B3: Price | C3: Unit$ | D3: YOY% | E3: US | F3: Chemicals | G3: _Macro | I3: -2.1297328 | J3: -1.6948423 | K3: -1.7972566 | L3: -1.8303581 | M3: -1.8054156 | N3: -1.7328657 | O3: -1.2925636 | P3: -1.1644435 | Q3: -1.0488744 | R3: -0.94688505 | S3: -0.8591857 | T3: -0.78370583 | U3: -0.71104223 | V3: -0.6386528 | W3: -0.56632078 | X3: -0.4938601 | Y3: -0.42966148 | Z3: -0.37875584 | AA3: -0.34498531 | AB3: -0.32628953 | AC3: -0.32086363 | AD3: -0.32446191 | AE3: -0.32597524 | AF3: -0.32283494 | AG3: -0.31523392 | AH3: -0.30334631 | AI3: -0.3117083 | AJ3: -0.30383125 | AK3: -0.30281314 | AL3: -0.30900103 | AM3: -0.32257187 | AN3: -0.34231937 | AO3: -0.36293763 | AP3: -0.38299552 | AQ3: -0.40239328 | AR3: -0.4210313
A4: IntermDem | B4: Quantity | C4: Mill$ | D4: YOY% | E4: US | F4: Chemicals | G4: _Macro | I4: -0.16822109 | J4: 2.3741691 | K4: 2.5660856 | L4: 2.6936049 | M4: 2.76545 | N4: 2.7889814 | O4: 3.2385066 | P4: 3.1694698 | Q4: 3.0821185 | R4: 2.9841123 | S4: 2.8810039 | T4: 2.7783699 | U4: 2.6851947 | V4: 2.60236 | W4: 2.5286853 | X4: 2.4631066 | Y4: 2.0203962 | Z4: 1.9893497 | AA4: 1.9716814 | AB4: 1.9666719 | AC4: 1.9732237 | AD4: 1.9880383 | AE4: 2.0032966 | AF4: 2.0165467 | AG4: 2.0272846 | AH4: 2.0350547 | AI4: 2.0050402 | AJ4: 2.0049684 | AK4: 2.0008314 | AL4: 1.9938594 | AM4: 1.9849814 | AN4: 1.9743032 | AO4: 1.9594046 | AP4: 1.9400014 | AQ4: 1.916471 | AR4: 1.8891373
A5: IntermDem | B5: Price | C5: Unit$ | D5: YOY% | E5: US | F5: Chemicals | G5: _Macro | I5: -1.8555071 | J5: -1.6993947 | K5: -1.7872914 | L5: -1.8043072 | M5: -1.762056 | N5: -1.6709512 | O5: -1.2609761 | P5: -1.1186527 | Q5: -0.99041557 | R5: -0.87706178 | S5: -0.77908641 | T5: -0.69412762 | U5: -0.61224449 | V5: -0.53087991 | W5: -0.44994467 | X5: -0.3693752 | Y5: -0.27305788 | Z5: -0.21007466 | AA5: -0.16449912 | AB5: -0.13418414 | AC5: -0.11727148 | AD5: -0.1095717 | AE5: -0.10031538 | AF5: -0.087081932 | AG5: -0.070130669 | AH5: -0.049691271 | AI5: -0.048778933 | AJ5: -0.032757599 | AK5: -0.023141367 | AL5: -0.020205628 | AM5: -0.024062308 | AN5: -0.033901457 | AO5: -0.046239767 | AP5: -0.060051862 | AQ5: -0.075174846 | AR5: -0.091439433
A6: EndowSupp | B6: Quantity | C6: Mill$ | D6: YOY% | E6: US | F6: Chemicals | G6: Labour | I6: -4.5269518 | J6: -0.086146176 | K6: 0.080191471 | L6: 0.21651857 | M6: 0.32936695 | N6: 0.42296779 | O6: 1.4073347 | P6: 1.4213061 | Q6: 1.37924 | R6: 1.2919635 | S6: 1.1673591 | T6: 1.0243573 | U6: 0.9188447 | V6: 0.86303794 | W6: 0.85574079 | X6: 0.89584494 | Y6: 0.37893942 | Z6: 0.44235235 | AA6: 0.48673329 | AB6: 0.5117057 | AC6: 0.51668036 | AD6: 0.50589973 | AE6: 0.50031167 | AF6: 0.50464833 | AG6: 0.51843971 | AH6: 0.54125893 | AI6: 0.52255058 | AJ6: 0.52630788 | AK6: 0.50395876 | AL6: 0.45698392 | AM6: 0.38646242 | AN6: 0.29896888 | AO6: 0.21749851 | AP6: 0.14802518 | AQ6: 0.090864949 | AR6: 0.046315607
A7: EndowSupp | B7: Price | C7: Unit$ | D7: YOY% | E7: US | F7: Chemicals | G7: Labour | I7: 1.5398968 | J7: 0.74863023 | K7: 0.63491195 | L7: 0.55426216 | M7: 0.49892449 | N7: 0.46222338 | O7: 0.48970559 | P7: 0.51245004 | Q7: 0.56211793 | R7: 0.63363546 | S7: 0.72327763 | T7: 0.81991404 | U7: 0.88831186 | V7: 0.92041063 | W7: 0.91670179 | X7: 0.87773991 | Y7: 0.94320571 | Z7: 0.88586205 | AA7: 0.84255654 | AB7: 0.81473494 | AC7: 0.80349714 | AD7: 0.80606079 | AE7: 0.80736125 | AF7: 0.80353439 | AG7: 0.79445684 | AH7: 0.78001601 | AI7: 0.74697423 | AJ7: 0.73972285 | AK7: 0.74533218 | AL7: 0.76307589 | AM7: 0.79251611 | AN7: 0.82947719 | AO7: 0.85852492 | AP7: 0.87586832 | AQ7: 0.88152933 | AR7: 0.8755098
A8: Output | B8: RealTaxRev | C8: Mill$ | D8: YOY | E8: US | F8: Chemicals | G8: _Macro | I8: -51.223572 | J8: 89.879623 | K8: 97.507492 | L8: 102.51268 | M8: 105.24519 | N8: 105.96253 | O8: 131.80357 | P8: 130.33311 | Q8: 128.04567 | R8: 125.20867 | S8: 122.01554 | T8: 118.6935 | U8: 115.68843 | V8: 113.09103 | W8: 110.89098 | X8: 109.07887 | Y8: 83.310608 | Z8: 82.003792 | AA8: 81.369698 | AB8: 81.388557 | AC8: 82.022278 | AD8: 83.127304 | AE8: 84.347916 | AF8: 85.573334 | AG8: 86.781845 | AH8: 87.947502 | AI8: 86.667183 | AJ8: 87.32518 | AK8: 87.645164 | AL8: 87.670761 | AM8: 87.434433 | AN8: 86.979401 | AO8: 86.385071 | AP8: 85.682854 | AQ8: 84.884529 | AR8: 83.999611
A9: FirmDem | B9: Quantity | C9: Mill$ | D9: YOY% | E9: US | F9: Chemicals | G9: Capital | I9: 5.8179483 | J9: 3.7031987 | K9: 3.8953209 | L9: 4.041544 | M9: 4.145401 | N9: 4.2084813 | O9: 3.9451838 | P9: 3.94153 | Q9: 3.9013016 | R9: 3.837409 | S9: 3.7593584 | T9: 3.6777048 | U9: 3.6109104 | V9: 3.5606811 | W9: 3.5242658 | X9: 3.4991868 | Y9: 3.6344719 | Z9: 3.6097131 | AA9: 3.5837379 | AB9: 3.5576379 | AC9: 3.5318732 | AD9: 3.5063348 | AE9: 3.481195 | AF9: 3.4558151 | AG9: 3.4295704 | AH9: 3.4018986 | AI9: 3.4110026 | AJ9: 3.3647838 | AK9: 3.3084118 | AL9: 3.2436957 | AM9: 3.1721022 | AN9: 3.0954196 | AO9: 3.0164225 | AP9: 2.9363103 | AQ9: 2.8556628 | AR9: 2.7749305
A10: FirmDem | B10: Price | C10: Unit$ | D10: YOY% | E10: US | F10: Chemicals | G10: Capital | I10: 1.1407044 | J10: -0.83042634 | K10: -1.046042 | L10: -1.2049221 | M10: -1.3161957 | N10: -1.3877952 | O10: -1.6655661 | P10: -1.6373426 | Q10: -1.5863498 | R10: -1.5217603 | S10: -1.4503137 | T10: -1.3787453 | U10: -1.3169303 | V10: -1.2656505 | W10: -1.2233979 | X10: -1.1887885 | Y10: -0.92295355 | Z10: -0.90968895 | AA10: -0.9010092 | AB10: -0.89515728 | AC10: -0.89067507 | AD10: -0.8853398 | AE10: -0.87524819 | AF10: -0.8597911 | AG10: -0.83939409 | AH10: -0.8144834 | AI10: -0.78406715 | AJ10: -0.75787431 | AK10: -0.73490685 | AL10: -0.71589953 | AM10: -0.70126802 | AN10: -0.69025087 | AO10: -0.67885143 | AP10: -0.66656011 | AQ10: -0.6538893 | AR10: -0.64127064
A11: FirmDem | B11: RealTaxRev | C11: Mill$ | D11: YOY | E11: US | F11: Chemicals | G11: Capital | I11: 222.82092 | J11: 133.86298 | K11: 139.61432 | L11: 143.44681 | M11: 145.43802 | N11: 145.59932 | O11: 120.89893 | P11: 118.91563 | Q11: 116.80743 | R11: 114.73415 | S11: 112.81957 | T11: 111.13781 | U11: 109.68672 | V11: 108.43603 | W11: 107.35831 | X11: 106.42702 | Y11: 117.91558 | Z11: 117.33562 | AA11: 117.17924 | AB11: 117.50271 | AC11: 118.34003 | AD11: 119.63042 | AE11: 121.09834 | AF11: 122.64648 | AG11: 124.24654 | AH11: 125.86703 | AI11: 130.63899 | AJ11: 131.63864 | AK11: 132.10448 | AL11: 132.05911 | AM11: 131.52216 | AN11: 130.58998 | AO11: 129.58502 | AP11: 128.59009 | AQ11: 127.60687 | AR11: 126.63287

Sheet US SAM
A1: ASAM | B1: 1 m_pdr | C1: 2 m_wht | D1: 3 m_gro | E1: 4 m_v_f | F1: 5 m_osd | G1: 6 m_c_b | H1: 7 m_pfb | I1: 8 m_ocr | J1: 9 m_ctl | K1: 10 m_oap | L1: 11 m_rmk | M1: 12 m_wol | N1: 13 m_frs | O1: 14 m_fsh | P1: 15 m_coa | Q1: 16 m_oil | R1: 17 m_gas | S1: 18 m_oxt | T1: 19 m_cmt | U1: 20 m_omt | V1: 21 m_vol | W1: 22 m_mil | X1: 23 m_pcr | Y1: 24 m_sgr | Z1: 25 m_ofd | AA1: 26 m_b_t | AB1: 27 m_tex | AC1: 28 m_wap | AD1: 29 m_lea | AE1: 30 m_lum | AF1: 31 m_ppp | AG1: 32 m_p_c | AH1: 33 m_chm | AI1: 34 m_bph | AJ1: 35 m_rpp | AK1: 36 m_nmm | AL1: 37 m_i_s | AM1: 38 m_nfm | AN1: 39 m_fmp | AO1: 40 m_ele | AP1: 41 m_eeq | AQ1: 42 m_ome | AR1: 43 m_mvh | AS1: 44 m_otn | AT1: 45 m_omf | AU1: 46 m_TnD | AV1: 47 m_NuclearBL | AW1: 48 m_CoalBL | AX1: 49 m_GasBL | AY1: 50 m_WindBL | AZ1: 51 m_HydroBL | BA1: 52 m_OilBL | BB1: 53 m_OtherBL | BC1: 54 m_GasP | BD1: 55 m_HydroP | BE1: 56 m_OilP | BF1: 57 m_SolarP | BG1: 58 m_gdt | BH1: 59 m_wtr | BI1: 60 m_cns | BJ1: 61 m_trd | BK1: 62 m_afs | BL1: 63 m_otp | BM1: 64 m_wtp | BN1: 65 m_atp | BO1: 66 m_whs | BP1: 67 m_cmn | BQ1: 68 m_ofi | BR1: 69 m_ins | BS1: 70 m_rsa | BT1: 71 m_obs | BU1: 72 m_ros | BV1: 73 m_osg | BW1: 74 m_edu | BX1: 75 m_hht | BY1: 76 m_dwe | BZ1: 77 d_pdr | CA1: 78 d_wht | CB1: 79 d_gro | CC1: 80 d_v_f | CD1: 81 d_osd | CE1: 82 d_c_b | CF1: 83 d_pfb | CG1: 84 d_ocr | CH1: 85 d_ctl | CI1: 86 d_oap | CJ1: 87 d_rmk | CK1: 88 d_wol | CL1: 89 d_frs | CM1: 90 d_fsh | CN1: 91 d_coa | CO1: 92 d_oil | CP1: 93 d_gas | CQ1: 94 d_oxt | CR1: 95 d_cmt | CS1: 96 d_omt | CT1: 97 d_vol | CU1: 98 d_mil | CV1: 99 d_pcr | CW1: 100 d_sgr | CX1: 101 d_ofd | CY1: 102 d_b_t | CZ1: 103 d_tex | DA1: 104 d_wap | DB1: 105 d_lea | DC1: 106 d_lum | DD1: 107 d_ppp | DE1: 108 d_p_c | DF1: 109 d_chm | DG1: 110 d_bph | DH1: 111 d_rpp | DI1: 112 d_nmm | DJ1: 113 d_i_s | DK1: 114 d_nfm | DL1: 115 d_fmp | DM1: 116 d_ele | DN1: 117 d_eeq | DO1: 118 d_ome | DP1: 119 d_mvh | DQ1: 120 d_otn | DR1: 121 d_omf | DS1: 122 d_TnD | DT1: 123 d_NuclearBL | DU1: 124 d_CoalBL | DV1: 125 d_GasBL | DW1: 126 d_WindBL | DX1: 127 d_HydroBL | DY1: 128 d_OilBL | DZ1: 129 d_OtherBL | EA1: 130 d_GasP | EB1: 131 d_HydroP | EC1: 132 d_OilP | ED1: 133 d_SolarP | EE1: 134 d_gdt | EF1: 135 d_wtr | EG1: 136 d_cns | EH1: 137 d_trd | EI1: 138 d_afs | EJ1: 139 d_otp | EK1: 140 d_wtp | EL1: 141 d_atp | EM1: 142 d_whs | EN1: 143 d_cmn | EO1: 144 d_ofi | EP1: 145 d_ins | EQ1: 146 d_rsa | ER1: 147 d_obs | ES1: 148 d_ros | ET1: 149 d_osg | EU1: 150 d_edu | EV1: 151 d_hht | EW1: 152 d_dwe | EX1: 153 a_pdr | EY1: 154 a_wht | EZ1: 155 a_gro | FA1: 156 a_v_f | FB1: 157 a_osd | FC1: 158 a_c_b | FD1: 159 a_pfb | FE1: 160 a_ocr | FF1: 161 a_ctl | FG1: 162 a_oap | FH1: 163 a_rmk | FI1: 164 a_wol | FJ1: 165 a_frs | FK1: 166 a_fsh | FL1: 167 a_coa | FM1: 168 a_oil | FN1: 169 a_gas | FO1: 170 a_oxt | FP1: 171 a_cmt | FQ1: 172 a_omt | FR1: 173 a_vol | FS1: 174 a_mil | FT1: 175 a_pcr | FU1: 176 a_sgr | FV1: 177 a_ofd | FW1: 178 a_b_t | FX1: 179 a_tex | FY1: 180 a_wap | FZ1: 181 a_lea | GA1: 182 a_lum | GB1: 183 a_ppp | GC1: 184 a_p_c | GD1: 185 a_chm | GE1: 186 a_bph | GF1: 187 a_rpp | GG1: 188 a_nmm | GH1: 189 a_i_s | GI1: 190 a_nfm | GJ1: 191 a_fmp | GK1: 192 a_ele | GL1: 193 a_eeq | GM1: 194 a_ome | GN1: 195 a_mvh | GO1: 196 a_otn | GP1: 197 a_omf | GQ1: 198 a_TnD | GR1: 199 a_NuclearBL | GS1: 200 a_CoalBL | GT1: 201 a_GasBL | GU1: 202 a_WindBL | GV1: 203 a_HydroBL | GW1: 204 a_OilBL | GX1: 205 a_OtherBL | GY1: 206 a_GasP | GZ1: 207 a_HydroP | HA1: 208 a_OilP | HB1: 209 a_SolarP | HC1: 210 a_gdt | HD1: 211 a_wtr | HE1: 212 a_cns | HF1: 213 a_trd | HG1: 214 a_afs | HH1: 215 a_otp | HI1: 216 a_wtp | HJ1: 217 a_atp | HK1: 218 a_whs | HL1: 219 a_cmn | HM1: 220 a_ofi | HN1: 221 a_ins | HO1: 222 a_rsa | HP1: 223 a_obs | HQ1: 224 a_ros | HR1: 225 a_osg | HS1: 226 a_edu | HT1: 227 a_hht | HU1: 228 a_dwe | HV1: 229 Land | HW1: 230 UnSklab | HX1: 231 SKlab | HY1: 232 Capital | HZ1: 233 NatlRes | IA1: 234 tmm_world | IB1: 235 tee_world | IC1: 236 tssm_T1pdr | ID1: 237 tssm_T2wht | IE1: 238 tssm_T3gro | IF1: 239 tssm_T4v_f | IG1: 240 tssm_T5osd | IH1: 241 tssm_T6c_b | II1: 242 tssm_T7pfb | IJ1: 243 tssm_T8ocr | IK1: 244 tssm_T9ctl | IL1: 245 tssm_T10oap | IM1: 246 tssm_T11rmk | IN1: 247 tssm_T12wol | IO1: 248 tssm_T13frs | IP1: 249 tssm_T14fsh | IQ1: 250 tssm_T15coa | IR1: 251 tssm_T16oil | IS1: 252 tssm_T17gas | IT1: 253 tssm_T18oxt | IU1: 254 tssm_T19cmt | IV1: 255 tssm_T20omt | IW1: 256 tssm_T21vol | IX1: 257 tssm_T22mil | IY1: 258 tssm_T23pcr | IZ1: 259 tssm_T24sgr | JA1: 260 tssm_T25ofd | JB1: 261 tssm_T26b_t | JC1: 262 tssm_T27tex | JD1: 263 tssm_T28wap | JE1: 264 tssm_T29lea | JF1: 265 tssm_T30lum | JG1: 266 tssm_T31ppp | JH1: 267 tssm_T32p_c | JI1: 268 tssm_T33chm | JJ1: 269 tssm_T34bph | JK1: 270 tssm_T35rpp | JL1: 271 tssm_T36nmm | JM1: 272 tssm_T37i_s | JN1: 273 tssm_T38nfm | JO1: 274 tssm_T39fmp | JP1: 275 tssm_T40ele | JQ1: 276 tssm_T41eeq | JR1: 277 tssm_T42ome | JS1: 278 tssm_T43mvh | JT1: 279 tssm_T44otn | JU1: 280 tssm_T45omf | JV1: 281 tssm_T46TnD | JW1: 282 tssm_T47Nucl | JX1: 283 tssm_T48Coal | JY1: 284 tssm_T49GasB | JZ1: 285 tssm_T50Wind | KA1: 286 tssm_T51Hydr | KB1: 287 tssm_T52OilB | KC1: 288 tssm_T53Othe | KD1: 289 tssm_T54GasP | KE1: 290 tssm_T55Hydr | KF1: 291 tssm_T56OilP | KG1: 292 tssm_T57Sola | KH1: 293 tssm_T58gdt | KI1: 294 tssm_T59wtr | KJ1: 295 tssm_T60cns | KK1: 296 tssm_T61trd | KL1: 297 tssm_T62afs | KM1: 298 tssm_T63otp | KN1: 299 tssm_T64wtp | KO1: 300 tssm_T65atp | KP1: 301 tssm_T66whs | KQ1: 302 tssm_T67cmn | KR1: 303 tssm_T68ofi | KS1: 304 tssm_T69ins | KT1: 305 tssm_T70rsa | KU1: 306 tssm_T71obs | KV1: 307 tssm_T72ros | KW1: 308 tssm_T73osg | KX1: 309 tssm_T74edu | KY1: 310 tssm_T75hht | KZ1: 311 tssm_T76dwe | LA1: 312 tssd_T1pdr | LB1: 313 tssd_T2wht | LC1: 314 tssd_T3gro | LD1: 315 tssd_T4v_f | LE1: 316 tssd_T5osd | LF1: 317 tssd_T6c_b | LG1: 318 tssd_T7pfb | LH1: 319 tssd_T8ocr | LI1: 320 tssd_T9ctl | LJ1: 321 tssd_T10oap | LK1: 322 tssd_T11rmk | LL1: 323 tssd_T12wol | LM1: 324 tssd_T13frs | LN1: 325 tssd_T14fsh | LO1: 326 tssd_T15coa | LP1: 327 tssd_T16oil | LQ1: 328 tssd_T17gas | LR1: 329 tssd_T18oxt | LS1: 330 tssd_T19cmt | LT1: 331 tssd_T20omt | LU1: 332 tssd_T21vol | LV1: 333 tssd_T22mil | LW1: 334 tssd_T23pcr | LX1: 335 tssd_T24sgr | LY1: 336 tssd_T25ofd | LZ1: 337 tssd_T26b_t | MA1: 338 tssd_T27tex | MB1: 339 tssd_T28wap | MC1: 340 tssd_T29lea | MD1: 341 tssd_T30lum | ME1: 342 tssd_T31ppp | MF1: 343 tssd_T32p_c | MG1: 344 tssd_T33chm | MH1: 345 tssd_T34bph | MI1: 346 tssd_T35rpp | MJ1: 347 tssd_T36nmm | MK1: 348 tssd_T37i_s | ML1: 349 tssd_T38nfm | MM1: 350 tssd_T39fmp | MN1: 351 tssd_T40ele | MO1: 352 tssd_T41eeq | MP1: 353 tssd_T42ome | MQ1: 354 tssd_T43mvh | MR1: 355 tssd_T44otn | MS1: 356 tssd_T45omf | MT1: 357 tssd_T46TnD | MU1: 358 tssd_T47Nucl | MV1: 359 tssd_T48Coal | MW1: 360 tssd_T49GasB | MX1: 361 tssd_T50Wind | MY1: 362 tssd_T51Hydr | MZ1: 363 tssd_T52OilB | NA1: 364 tssd_T53Othe | NB1: 365 tssd_T54GasP | NC1: 366 tssd_T55Hydr | ND1: 367 tssd_T56OilP | NE1: 368 tssd_T57Sola | NF1: 369 tssd_T58gdt | NG1: 370 tssd_T59wtr | NH1: 371 tssd_T60cns | NI1: 372 tssd_T61trd | NJ1: 373 tssd_T62afs | NK1: 374 tssd_T63otp | NL1: 375 tssd_T64wtp | NM1: 376 tssd_T65atp | NN1: 377 tssd_T66whs | NO1: 378 tssd_T67cmn | NP1: 379 tssd_T68ofi | NQ1: 380 tssd_T69ins | NR1: 381 tssd_T70rsa | NS1: 382 tssd_T71obs | NT1: 383 tssd_T72ros | NU1: 384 tssd_T73osg | NV1: 385 tssd_T74edu | NW1: 386 tssd_T75hht | NX1: 387 tssd_T76dwe | NY1: 388 tf_Land | NZ1: 389 tf_UnSklab | OA1: 390 tf_SKlab | OB1: 391 tf_Capital | OC1: 392 tf_NatlRes | OD1: 393 otp_world | OE1: 394 wtp_world | OF1: 395 atp_world | OG1: 396 otp_pvst | OH1: 397 wtp_pvst | OI1: 398 atp_pvst | OJ1: 399 ww_world | OK1: 400 REGHOUS | OL1: 401 PRIV | OM1: 402 PRODTAX | ON1: 403 DIRTAX | OO1: 404 GOVT | OP1: 405 CGDS | OQ1: Total
A2: 1 m_pdr | B2: 0 | C2: 0 | D2: 0 | E2: 0 | F2: 0 | G2: 0 | H2: 0 | I2: 0 | J2: 0 | K2: 0 | L2: 0 | M2: 0 | N2: 0 | O2: 0 | P2: 0 | Q2: 0 | R2: 0 | S2: 0 | T2: 0 | U2: 0 | V2: 0 | W2: 0 | X2: 0 | Y2: 0 | Z2: 0 | AA2: 0 | AB2: 0 | AC2: 0 | AD2: 0 | AE2: 0 | AF2: 0 | AG2: 0 | AH2: 0 | AI2: 0 | AJ2: 0 | AK2: 0 | AL2: 0 | AM2: 0 | AN2: 0 | AO2: 0 | AP2: 0 | AQ2: 0 | AR2: 0 | AS2: 0 | AT2: 0 | AU2: 0 | AV2: 0 | AW2: 0 | AX2: 0 | AY2: 0 | AZ2: 0 | BA2: 0 | BB2: 0 | BC2: 0 | BD2: 0 | BE2: 0 | BF2: 0 | BG2: 0 | BH2: 0 | BI2: 0 | BJ2: 0 | BK2: 0 | BL2: 0 | BM2: 0 | BN2: 0 | BO2: 0 | BP2: 0 | BQ2: 0 | BR2: 0 | BS2: 0 | BT2: 0 | BU2: 0 | BV2: 0 | BW2: 0 | BX2: 0 | BY2: 0 | BZ2: 0 | CA2: 0 | CB2: 0 | CC2: 0 | CD2: 0 | CE2: 0 | CF2: 0 | CG2: 0 | CH2: 0 | CI2: 0 | CJ2: 0 | CK2: 0 | CL2: 0 | CM2: 0 | CN2: 0 | CO2: 0 | CP2: 0 | CQ2: 0 | CR2: 0 | CS2: 0 | CT2: 0 | CU2: 0 | CV2: 0 | CW2: 0 | CX2: 0 | CY2: 0 | CZ2: 0 | DA2: 0 | DB2: 0 | DC2: 0 | DD2: 0 | DE2: 0 | DF2: 0 | DG2: 0 | DH2: 0 | DI2: 0 | DJ2: 0 | DK2: 0 | DL2: 0 | DM2: 0 | DN2: 0 | DO2: 0 | DP2: 0 | DQ2: 0 | DR2: 0 | DS2: 0 | DT2: 0 | DU2: 0 | DV2: 0 | DW2: 0 | DX2: 0 | DY2: 0 | DZ2: 0 | EA2: 0 | EB2: 0 | EC2: 0 | ED2: 0 | EE2: 0 | EF2: 0 | EG2: 0 | EH2: 0 | EI2: 0 | EJ2: 0 | EK2: 0 | EL2: 0 | EM2: 0 | EN2: 0 | EO2: 0 | EP2: 0 | EQ2: 0 | ER2: 0 | ES2: 0 | ET2: 0 | EU2: 0 | EV2: 0 | EW2: 0 | EX2: 0.144807 | EY2: 0.592334 | EZ2: 0.007381 | FA2: 0.001067 | FB2: 0.014947 | FC2: 3.9e-05 | FD2: 0.006424 | FE2: 0.000459 | FF2: 0.419314 | FG2: 0.883453 | FH2: 0.228135 | FI2: 0.000767 | FJ2: 0.009131 | FK2: 1.6e-05 | FL2: 0 | FM2: 5e-05 | FN2: 7e-06 | FO2: 1e-05 | FP2: 0.011069 | FQ2: 0.001212 | FR2: 0.002187 | FS2: 0.005053 | FT2: 0.137388 | FU2: 0.005251 | FV2: 14.939363 | FW2: 0.077516 | FX2: 0.00406 | FY2: 5.9e-05 | FZ2: 9e-06 | GA2: 0.00055 | GB2: 0.000721 | GC2: 0.002348 | GD2: 0.493525 | GE2: 0.002716 | GF2: 0.001449 | GG2: 8.7e-05 | GH2: 8e-05 | GI2: 0.003677 | GJ2: 1.6e-05 | GK2: 8e-05 | GL2: 0 | GM2: 9e-06 | GN2: 0 | GO2: 0 | GP2: 0.00285 | GQ2: 0 | GR2: 0 | GS2: 0 | GT2: 0 | GU2: 0 | GV2: 0 | GW2: 0 | GX2: 0 | GY2: 0 | GZ2: 0 | HA2: 0 | HB2: 0 | HC2: 1e-06 | HD2: 2e-06 | HE2: 0.000296 | HF2: 0.229912 | HG2: 0.121726 | HH2: 0.000767 | HI2: 0 | HJ2: 5.7e-05 | HK2: 0.000818 | HL2: 5.2e-05 | HM2: 6e-06 | HN2: 5e-06 | HO2: 3e-05 | HP2: 0.03884 | HQ2: 0.014068 | HR2: 2.1e-05 | HS2: 7.7e-05 | HT2: 7.3e-05 | HU2: 4.5e-05 | HV2: 0 | HW2: 0 | HX2: 0 | HY2: 0 | HZ2: 0 | IA2: 0 | IB2: 0 | IC2: 0 | ID2: 0 | IE2: 0 | IF2: 0 | IG2: 0 | IH2: 0 | II2: 0 | IJ2: 0 | IK2: 0 | IL2: 0 | IM2: 0 | IN2: 0 | IO2: 0 | IP2: 0 | IQ2: 0 | IR2: 0 | IS2: 0 | IT2: 0 | IU2: 0 | IV2: 0 | IW2: 0 | IX2: 0 | IY2: 0 | IZ2: 0 | JA2: 0 | JB2: 0 | JC2: 0 | JD2: 0 | JE2: 0 | JF2: 0 | JG2: 0 | JH2: 0 | JI2: 0 | JJ2: 0 | JK2: 0 | JL2: 0 | JM2: 0 | JN2: 0 | JO2: 0 | JP2: 0 | JQ2: 0 | JR2: 0 | JS2: 0 | JT2: 0 | JU2: 0 | JV2: 0 | JW2: 0 | JX2: 0 | JY2: 0 | JZ2: 0 | KA2: 0 | KB2: 0 | KC2: 0 | KD2: 0 | KE2: 0 | KF2: 0 | KG2: 0 | KH2: 0 | KI2: 0 | KJ2: 0 | KK2: 0 | KL2: 0 | KM2: 0 | KN2: 0 | KO2: 0 | KP2: 0 | KQ2: 0 | KR2: 0 | KS2: 0 | KT2: 0 | KU2: 0 | KV2: 0 | KW2: 0 | KX2: 0 | KY2: 0 | KZ2: 0 | LA2: 0 | LB2: 0 | LC2: 0 | LD2: 0 | LE2: 0 | LF2: 0 | LG2: 0 | LH2: 0 | LI2: 0 | LJ2: 0 | LK2: 0 | LL2: 0 | LM2: 0 | LN2: 0 | LO2: 0 | LP2: 0 | LQ2: 0 | LR2: 0 | LS2: 0 | LT2: 0 | LU2: 0 | LV2: 0 | LW2: 0 | LX2: 0 | LY2: 0 | LZ2: 0 | MA2: 0 | MB2: 0 | MC2: 0 | MD2: 0 | ME2: 0 | MF2: 0 | MG2: 0 | MH2: 0 | MI2: 0 | MJ2: 0 | MK2: 0 | ML2: 0 | MM2: 0 | MN2: 0 | MO2: 0 | MP2: 0 | MQ2: 0 | MR2: 0 | MS2: 0 | MT2: 0 | MU2: 0 | MV2: 0 | MW2: 0 | MX2: 0 | MY2: 0 | MZ2: 0 | NA2: 0 | NB2: 0 | NC2: 0 | ND2: 0 | NE2: 0 | NF2: 0 | NG2: 0 | NH2: 0 | NI2: 0 | NJ2: 0 | NK2: 0 | NL2: 0 | NM2: 0 | NN2: 0 | NO2: 0 | NP2: 0 | NQ2: 0 | NR2: 0 | NS2: 0 | NT2: 0 | NU2: 0 | NV2: 0 | NW2: 0 | NX2: 0 | NY2: 0 | NZ2: 0 | OA2: 0 | OB2: 0 | OC2: 0 | OD2: 0 | OE2: 0 | OF2: 0 | OG2: 0 | OH2: 0 | OI2: 0 | OJ2: 0 | OK2: 0 | OL2: 0.000693 | OM2: 0 | ON2: 0 | OO2: 2.9e-05 | OP2: 0.000162 | OQ2: 18.407297
A3: 2 m_wht | B3: 0 | C3: 0 | D3: 0 | E3: 0 | F3: 0 | G3: 0 | H3: 0 | I3: 0 | J3: 0 | K3: 0 | L3: 0 | M3: 0 | N3: 0 | O3: 0 | P3: 0 | Q3: 0 | R3: 0 | S3: 0 | T3: 0 | U3: 0 | V3: 0 | W3: 0 | X3: 0 | Y3: 0 | Z3: 0 | AA3: 0 | AB3: 0 | AC3: 0 | AD3: 0 | AE3: 0 | AF3: 0 | AG3: 0 | AH3: 0 | AI3: 0 | AJ3: 0 | AK3: 0 | AL3: 0 | AM3: 0 | AN3: 0 | AO3: 0 | AP3: 0 | AQ3: 0 | AR3: 0 | AS3: 0 | AT3: 0 | AU3: 0 | AV3: 0 | AW3: 0 | AX3: 0 | AY3: 0 | AZ3: 0 | BA3: 0 | BB3: 0 | BC3: 0 | BD3: 0 | BE3: 0 | BF3: 0 | BG3: 0 | BH3: 0 | BI3: 0 | BJ3: 0 | BK3: 0 | BL3: 0 | BM3: 0 | BN3: 0 | BO3: 0 | BP3: 0 | BQ3: 0 | BR3: 0 | BS3: 0 | BT3: 0 | BU3: 0 | BV3: 0 | BW3: 0 | BX3: 0 | BY3: 0 | BZ3: 0 | CA3: 0 | CB3: 0 | CC3: 0 | CD3: 0 | CE3: 0 | CF3: 0 | CG3: 0 | CH3: 0 | CI3: 0 | CJ3: 0 | CK3: 0 | CL3: 0 | CM3: 0 | CN3: 0 | CO3: 0 | CP3: 0 | CQ3: 0 | CR3: 0 | CS3: 0 | CT3: 0 | CU3: 0 | CV3: 0 | CW3: 0 | CX3: 0 | CY3: 0 | CZ3: 0 | DA3: 0 | DB3: 0 | DC3: 0 | DD3: 0 | DE3: 0 | DF3: 0 | DG3: 0 | DH3: 0 | DI3: 0 | DJ3: 0 | DK3: 0 | DL3: 0 | DM3: 0 | DN3: 0 | DO3: 0 | DP3: 0 | DQ3: 0 | DR3: 0 | DS3: 0 | DT3: 0 | DU3: 0 | DV3: 0 | DW3: 0 | DX3: 0 | DY3: 0 | DZ3: 0 | EA3: 0 | EB3: 0 | EC3: 0 | ED3: 0 | EE3: 0 | EF3: 0 | EG3: 0 | EH3: 0 | EI3: 0 | EJ3: 0 | EK3: 0 | EL3: 0 | EM3: 0 | EN3: 0 | EO3: 0 | EP3: 0 | EQ3: 0 | ER3: 0 | ES3: 0 | ET3: 0 | EU3: 0 | EV3: 0 | EW3: 0 | EX3: 5.857885 | EY3: 40.368114 | EZ3: 2.160688 | FA3: 0.222501 | FB3: 0.022575 | FC3: 0.000637 | FD3: 0.019936 | FE3: 0.066338 | FF3: 19.310255 | FG3: 39.103645 | FH3: 11.166458 | FI3: 0.034826 | FJ3: 0.339734 | FK3: 0.004347 | FL3: 2e-06 | FM3: 0.002624 | FN3: 0.000278 | FO3: 0.001533 | FP3: 1.156849 | FQ3: 1.203462 | FR3: 0.413914 | FS3: 2.315489 | FT3: 4.44275 | FU3: 1.089898 | FV3: 796.51617 | FW3: 17.112671 | FX3: 0.256419 | FY3: 0.087031 | FZ3: 0.128031 | GA3: 0.028992 | GB3: 0.008851 | GC3: 0.097985 | GD3: 13.33734 | GE3: 2.081834 | GF3: 5.588284 | GG3: 0.006182 | GH3: 0.003291 | GI3: 0.151581 | GJ3: 0.006868 | GK3: 0.003896 | GL3: 0.000332 | GM3: 0.000641 | GN3: 6.6e-05 | GO3: 4.4e-05 | GP3: 0.07056 | GQ3: 1.6e-05 | GR3: 1.1e-05 | GS3: 1.2e-05 | GT3: 2e-06 | GU3: 3e-06 | GV3: 1e-06 | GW3: 0 | GX3: 1e-06 | GY3: 1e-06 | GZ3: 0 | HA3: 1e-06 | HB3: 0 | HC3: 0.000934 | HD3: 0.075146 | HE3: 0.026627 | HF3: 0.031079 | HG3: 17.61566 | HH3: 0.032085 | HI3: 0.000303 | HJ3: 0.002369 | HK3: 0.025986 | HL3: 0.04345 | HM3: 0.060263 | HN3: 0.050848 | HO3: 0.032528 | HP3: 1.66095 | HQ3: 0.673325 | HR3: 1.757806 | HS3: 0.039228 | HT3: 2.204378 | HU3: 0.04085 | HV3: 0 | HW3: 0 | HX3: 0 | HY3: 0 | HZ3: 0 | IA3: 0 | IB3: 0 | IC3: 0 | ID3: 0 | IE3: 0 | IF3: 0 | IG3: 0 | IH3: 0 | II3: 0 | IJ3: 0 | IK3: 0 | IL3: 0 | IM3: 0 | IN3: 0 | IO3: 0 | IP3: 0 | IQ3: 0 | IR3: 0 | IS3: 0 | IT3: 0 | IU3: 0 | IV3: 0 | IW3: 0 | IX3: 0 | IY3: 0 | IZ3: 0 | JA3: 0 | JB3: 0 | JC3: 0 | JD3: 0 | JE3: 0 | JF3: 0 | JG3: 0 | JH3: 0 | JI3: 0 | JJ3: 0 | JK3: 0 | JL3: 0 | JM3: 0 | JN3: 0 | JO3: 0 | JP3: 0 | JQ3: 0 | JR3: 0 | JS3: 0 | JT3: 0 | JU3: 0 | JV3: 0 | JW3: 0 | JX3: 0 | JY3: 0 | JZ3: 0 | KA3: 0 | KB3: 0 | KC3: 0 | KD3: 0 | KE3: 0 | KF3: 0 | KG3: 0 | KH3: 0 | KI3: 0 | KJ3: 0 | KK3: 0 | KL3: 0 | KM3: 0 | KN3: 0 | KO3: 0 | KP3: 0 | KQ3: 0 | KR3: 0 | KS3: 0 | KT3: 0 | KU3: 0 | KV3: 0 | KW3: 0 | KX3: 0 | KY3: 0 | KZ3: 0 | LA3: 0 | LB3: 0 | LC3: 0 | LD3: 0 | LE3: 0 | LF3: 0 | LG3: 0 | LH3: 0 | LI3: 0 | LJ3: 0 | LK3: 0 | LL3: 0 | LM3: 0 | LN3: 0 | LO3: 0 | LP3: 0 | LQ3: 0 | LR3: 0 | LS3: 0 | LT3: 0 | LU3: 0 | LV3: 0 | LW3: 0 | LX3: 0 | LY3: 0 | LZ3: 0 | MA3: 0 | MB3: 0 | MC3: 0 | MD3: 0 | ME3: 0 | MF3: 0 | MG3: 0 | MH3: 0 | MI3: 0 | MJ3: 0 | MK3: 0 | ML3: 0 | MM3: 0 | MN3: 0 | MO3: 0 | MP3: 0 | MQ3: 0 | MR3: 0 | MS3: 0 | MT3: 0 | MU3: 0 | MV3: 0 | MW3: 0 | MX3: 0 | MY3: 0 | MZ3: 0 | NA3: 0 | NB3: 0 | NC3: 0 | ND3: 0 | NE3: 0 | NF3: 0 | NG3: 0 | NH3: 0 | NI3: 0 | NJ3: 0 | NK3: 0 | NL3: 0 | NM3: 0 | NN3: 0 | NO3: 0 | NP3: 0 | NQ3: 0 | NR3: 0 | NS3: 0 | NT3: 0 | NU3: 0 | NV3: 0 | NW3: 0 | NX3: 0 | NY3: 0 | NZ3: 0 | OA3: 0 | OB3: 0 | OC3: 0 | OD3: 0 | OE3: 0 | OF3: 0 | OG3: 0 | OH3: 0 | OI3: 0 | OJ3: 0 | OK3: 0 | OL3: 0.596011 | OM3: 0 | ON3: 0 | OO3: 0.034058 | OP3: 0.007682 | OQ3: 989.80342
A4: 3 m_gro | B4: 0 | C4: 0 | D4: 0 | E4: 0 | F4: 0 | G4: 0 | H4: 0 | I4: 0 | J4: 0 | K4: 0 | L4: 0 | M4: 0 | N4: 0 | O4: 0 | P4: 0 | Q4: 0 | R4: 0 | S4: 0 | T4: 0 | U4: 0 | V4: 0 | W4: 0 | X4: 0 | Y4: 0 | Z4: 0 | AA4: 0 | AB4: 0 | AC4: 0 | AD4: 0 | AE4: 0 | AF4: 0 | AG4: 0 | AH4: 0 | AI4: 0 | AJ4: 0 | AK4: 0 | AL4: 0 | AM4: 0 | AN4: 0 | AO4: 0 | AP4: 0 | AQ4: 0 | AR4: 0 | AS4: 0 | AT4: 0 | AU4: 0 | AV4: 0 | AW4: 0 | AX4: 0 | AY4: 0 | AZ4: 0 | BA4: 0 | BB4: 0 | BC4: 0 | BD4: 0 | BE4: 0 | BF4: 0 | BG4: 0 | BH4: 0 | BI4: 0 | BJ4: 0 | BK4: 0 | BL4: 0 | BM4: 0 | BN4: 0 | BO4: 0 | BP4: 0 | BQ4: 0 | BR4: 0 | BS4: 0 | BT4: 0 | BU4: 0 | BV4: 0 | BW4: 0 | BX4: 0 | BY4: 0 | BZ4: 0 | CA4: 0 | CB4: 0 | CC4: 0 | CD4: 0 | CE4: 0 | CF4: 0 | CG4: 0 | CH4: 0 | CI4: 0 | CJ4: 0 | CK4: 0 | CL4: 0 | CM4: 0 | CN4: 0 | CO4: 0 | CP4: 0 | CQ4: 0 | CR4: 0 | CS4: 0 | CT4: 0 | CU4: 0 | CV4: 0 | CW4: 0 | CX4: 0 | CY4: 0 | CZ4: 0 | DA4: 0 | DB4: 0 | DC4: 0 | DD4: 0 | DE4: 0 | DF4: 0 | DG4: 0 | DH4: 0 | DI4: 0 | DJ4: 0 | DK4: 0 | DL4: 0 | DM4: 0 | DN4: 0 | DO4: 0 | DP4: 0 | DQ4: 0 | DR4: 0 | DS4: 0 | DT4: 0 | DU4: 0 | DV4: 0 | DW4: 0 | DX4: 0 | DY4: 0 | DZ4: 0 | EA4: 0 | EB4: 0 | EC4: 0 | ED4: 0 | EE4: 0 | EF4: 0 | EG4: 0 | EH4: 0 | EI4: 0 | EJ4: 0 | EK4: 0 | EL4: 0 | EM4: 0 | EN4: 0 | EO4: 0 | EP4: 0 | EQ4: 0 | ER4: 0 | ES4: 0 | ET4: 0 | EU4: 0 | EV4: 0 | EW4: 0 | EX4: 0.008023 | EY4: 0.133456 | EZ4: 25.783201 | FA4: 0.153526 | FB4: 0.027958 | FC4: 0.000682 | FD4: 0.002274 | FE4: 0.002513 | FF4: 162.23567 | FG4: 157.6781 | FH4: 295.43399 | FI4: 0.352667 | FJ4: 7.07889 | FK4: 0.002362 | FL4: 1e-06 | FM4: 0.00075 | FN4: 0.002489 | FO4: 0.000794 | FP4: 10.95054 | FQ4: 8.318515 | FR4: 2.685355 | FS4: 15.356281 | FT4: 0.190273 | FU4: 2.818709 | FV4: 461.12146 | FW4: 89.161324 | FX4: 1.169749 | FY4: 0.80729 | FZ4: 0.240228 | GA4: 0.065765 | GB4: 0.028947 | GC4: 0.001809 | GD4: 5.426575 | GE4: 1.090778 | GF4: 2.273824 | GG4: 0.004978 | GH4: 3.3e-05 | GI4: 3e-06 | GJ4: 0.011598 | GK4: 0.005872 | GL4: 0.000472 | GM4: 0.000846 | GN4: 4.9e-05 | GO4: 0.000267 | GP4: 1.144199 | GQ4: 0.000128 | GR4: 8.4e-05 | GS4: 9.4e-05 | GT4: 1.4e-05 | GU4: 2e-05 | GV4: 6e-06 | GW4: 0 | GX4: 4e-06 | GY4: 1e-05 | GZ4: 0 | HA4: 9e-06 | HB4: 1e-06 | HC4: 0.025442 | HD4: 0.070321 | HE4: 2.098124 | HF4: 0.064917 | HG4: 51.856632 | HH4: 0.009003 | HI4: 0.000558 | HJ4: 0.025161 | HK4: 0.008959 | HL4: 0.170818 | HM4: 0.082853 | HN4: 0.069821 | HO4: 0.135057 | HP4: 8.903062 | HQ4: 7.224765 | HR4: 2.315092 | HS4: 0.06422 | HT4: 3.040934 | HU4: 0.076946 | HV4: 0 | HW4: 0 | HX4: 0 | HY4: 0 | HZ4: 0 | IA4: 0 | IB4: 0 | IC4: 0 | ID4: 0 | IE4: 0 | IF4: 0 | IG4: 0 | IH4: 0 | II4: 0 | IJ4: 0 | IK4: 0 | IL4: 0 | IM4: 0 | IN4: 0 | IO4: 0 | IP4: 0 | IQ4: 0 | IR4: 0 | IS4: 0 | IT4: 0 | IU4: 0 | IV4: 0 | IW4: 0 | IX4: 0 | IY4: 0 | IZ4: 0 | JA4: 0 | JB4: 0 | JC4: 0 | JD4: 0 | JE4: 0 | JF4: 0 | JG4: 0 | JH4: 0 | JI4: 0 | JJ4: 0 | JK4: 0 | JL4: 0 | JM4: 0 | JN4: 0 | JO4: 0 | JP4: 0 | JQ4: 0 | JR4: 0 | JS4: 0 | JT4: 0 | JU4: 0 | JV4: 0 | JW4: 0 | JX4: 0 | JY4: 0 | JZ4: 0 | KA4: 0 | KB4: 0 | KC4: 0 | KD4: 0 | KE4: 0 | KF4: 0 | KG4: 0 | KH4: 0 | KI4: 0 | KJ4: 0 | KK4: 0 | KL4: 0 | KM4: 0 | KN4: 0 | KO4: 0 | KP4: 0 | KQ4: 0 | KR4: 0 | KS4: 0 | KT4: 0 | KU4: 0 | KV4: 0 | KW4: 0 | KX4: 0 | KY4: 0 | KZ4: 0 | LA4: 0 | LB4: 0 | LC4: 0 | LD4: 0 | LE4: 0 | LF4: 0 | LG4: 0 | LH4: 0 | LI4: 0 | LJ4: 0 | LK4: 0 | LL4: 0 | LM4: 0 | LN4: 0 | LO4: 0 | LP4: 0 | LQ4: 0 | LR4: 0 | LS4: 0 | LT4: 0 | LU4: 0 | LV4: 0 | LW4: 0 | LX4: 0 | LY4: 0 | LZ4: 0 | MA4: 0 | MB4: 0 | MC4: 0 | MD4: 0 | ME4: 0 | MF4: 0 | MG4: 0 | MH4: 0 | MI4: 0 | MJ4: 0 | MK4: 0 | ML4: 0 | MM4: 0 | MN4: 0 | MO4: 0 | MP4: 0 | MQ4: 0 | MR4: 0 | MS4: 0 | MT4: 0 | MU4: 0 | MV4: 0 | MW4: 0 | MX4: 0 | MY4: 0 | MZ4: 0 | NA4: 0 | NB4: 0 | NC4: 0 | ND4: 0 | NE4: 0 | NF4: 0 | NG4: 0 | NH4: 0 | NI4: 0 | NJ4: 0 | NK4: 0 | NL4: 0 | NM4: 0 | NN4: 0 | NO4: 0 | NP4: 0 | NQ4: 0 | NR4: 0 | NS4: 0 | NT4: 0 | NU4: 0 | NV4: 0 | NW4: 0 | NX4: 0 | NY4: 0 | NZ4: 0 | OA4: 0 | OB4: 0 | OC4: 0 | OD4: 0 | OE4: 0 | OF4: 0 | OG4: 0 | OH4: 0 | OI4: 0 | OJ4: 0 | OK4: 0 | OL4: 292.83697 | OM4: 0 | ON4: 0 | OO4: 0.001669 | OP4: 2.544111 | OQ4: 1623.3989
A5: 4 m_v_f | B5: 0 | C5: 0 | D5: 0 | E5: 0 | F5: 0 | G5: 0 | H5: 0 | I5: 0 | J5: 0 | K5: 0 | L5: 0 | M5: 0 | N5: 0 | O5: 0 | P5: 0 | Q5: 0 | R5: 0 | S5: 0 | T5: 0 | U5: 0 | V5: 0 | W5: 0 | X5: 0 | Y5: 0 | Z5: 0 | AA5: 0 | AB5: 0 | AC5: 0 | AD5: 0 | AE5: 0 | AF5: 0 | AG5: 0 | AH5: 0 | AI5: 0 | AJ5: 0 | AK5: 0 | AL5: 0 | AM5: 0 | AN5: 0 | AO5: 0 | AP5: 0 | AQ5: 0 | AR5: 0 | AS5: 0 | AT5: 0 | AU5: 0 | AV5: 0 | AW5: 0 | AX5: 0 | AY5: 0 | AZ5: 0 | BA5: 0 | BB5: 0 | BC5: 0 | BD5: 0 | BE5: 0 | BF5: 0 | BG5: 0 | BH5: 0 | BI5: 0 | BJ5: 0 | BK5: 0 | BL5: 0 | BM5: 0 | BN5: 0 | BO5: 0 | BP5: 0 | BQ5: 0 | BR5: 0 | BS5: 0 | BT5: 0 | BU5: 0 | BV5: 0 | BW5: 0 | BX5: 0 | BY5: 0 | BZ5: 0 | CA5: 0 | CB5: 0 | CC5: 0 | CD5: 0 | CE5: 0 | CF5: 0 | CG5: 0 | CH5: 0 | CI5: 0 | CJ5: 0 | CK5: 0 | CL5: 0 | CM5: 0 | CN5: 0 | CO5: 0 | CP5: 0 | CQ5: 0 | CR5: 0 | CS5: 0 | CT5: 0 | CU5: 0 | CV5: 0 | CW5: 0 | CX5: 0 | CY5: 0 | CZ5: 0 | DA5: 0 | DB5: 0 | DC5: 0 | DD5: 0 | DE5: 0 | DF5: 0 | DG5: 0 | DH5: 0 | DI5: 0 | DJ5: 0 | DK5: 0 | DL5: 0 | DM5: 0 | DN5: 0 | DO5: 0 | DP5: 0 | DQ5: 0 | DR5: 0 | DS5: 0 | DT5: 0 | DU5: 0 | DV5: 0 | DW5: 0 | DX5: 0 | DY5: 0 | DZ5: 0 | EA5: 0 | EB5: 0 | EC5: 0 | ED5: 0 | EE5: 0 | EF5: 0 | EG5: 0 | EH5: 0 | EI5: 0 | EJ5: 0 | EK5: 0 | EL5: 0 | EM5: 0 | EN5: 0 | EO5: 0 | EP5: 0 | EQ5: 0 | ER5: 0 | ES5: 0 | ET5: 0 | EU5: 0 | EV5: 0 | EW5: 0 | EX5: 0.020067 | EY5: 0.099578 | EZ5: 0.571803 | FA5: 53.874329 | FB5: 0.291131 | FC5: 0.006552 | FD5: 0.004026 | FE5: 0.063401 | FF5: 57.982964 | FG5: 45.690456 | FH5: 36.686184 | FI5: 0.067565 | FJ5: 0.000276 | FK5: 0.024743 | FL5: 1.6e-05 | FM5: 0.009674 | FN5: 5e-05 | FO5: 0.002998 | FP5: 3.677377 | FQ5: 22.267759 | FR5: 8.263585 | FS5: 24.600365 | FT5: 50.793217 | FU5: 14.488631 | FV5: 7211.4814 | FW5: 524.09033 | FX5: 0.699389 | FY5: 0.512565 | FZ5: 0.40733 | GA5: 0.082817 | GB5: 0.042257 | GC5: 0.021593 | GD5: 8.22088 | GE5: 26.637333 | GF5: 0.278018 | GG5: 0.007736 | GH5: 1e-05 | GI5: 1.9e-05 | GJ5: 0.23169 | GK5: 0.258685 | GL5: 0.01669 | GM5: 0.031154 | GN5: 4.6e-05 | GO5: 0.064822 | GP5: 3.452574 | GQ5: 0.000578 | GR5: 0.000378 | GS5: 0.000424 | GT5: 6.1e-05 | GU5: 8.9e-05 | GV5: 2.8e-05 | GW5: 0 | GX5: 1.8e-05 | GY5: 4.7e-05 | GZ5: 0 | HA5: 3.9e-05 | HB5: 6e-06 | HC5: 0.11399 | HD5: 0.771111 | HE5: 0.473811 | HF5: 0.025496 | HG5: 189.45505 | HH5: 2.2e-05 | HI5: 0.029839 | HJ5: 1e-06 | HK5: 0.148042 | HL5: 0.123996 | HM5: 1.313133 | HN5: 0.879216 | HO5: 0.078745 | HP5: 2.831115 | HQ5: 792.51917 | HR5: 48.395622 | HS5: 0.358479 | HT5: 462.04514 | HU5: 0.120728 | HV5: 0 | HW5: 0 | HX5: 0 | HY5: 0 | HZ5: 0 | IA5: 0 | IB5: 0 | IC5: 0 | ID5: 0 | IE5: 0 | IF5: 0 | IG5: 0 | IH5: 0 | II5: 0 | IJ5: 0 | IK5: 0 | IL5: 0 | IM5: 0 | IN5: 0 | IO5: 0 | IP5: 0 | IQ5: 0 | IR5: 0 | IS5: 0 | IT5: 0 | IU5: 0 | IV5: 0 | IW5: 0 | IX5: 0 | IY5: 0 | IZ5: 0 | JA5: 0 | JB5: 0 | JC5: 0 | JD5: 0 | JE5: 0 | JF5: 0 | JG5: 0 | JH5: 0 | JI5: 0 | JJ5: 0 | JK5: 0 | JL5: 0 | JM5: 0 | JN5: 0 | JO5: 0 | JP5: 0 | JQ5: 0 | JR5: 0 | JS5: 0 | JT5: 0 | JU5: 0 | JV5: 0 | JW5: 0 | JX5: 0 | JY5: 0 | JZ5: 0 | KA5: 0 | KB5: 0 | KC5: 0 | KD5: 0 | KE5: 0 | KF5: 0 | KG5: 0 | KH5: 0 | KI5: 0 | KJ5: 0 | KK5: 0 | KL5: 0 | KM5: 0 | KN5: 0 | KO5: 0 | KP5: 0 | KQ5: 0 | KR5: 0 | KS5: 0 | KT5: 0 | KU5: 0 | KV5: 0 | KW5: 0 | KX5: 0 | KY5: 0 | KZ5: 0 | LA5: 0 | LB5: 0 | LC5: 0 | LD5: 0 | LE5: 0 | LF5: 0 | LG5: 0 | LH5: 0 | LI5: 0 | LJ5: 0 | LK5: 0 | LL5: 0 | LM5: 0 | LN5: 0 | LO5: 0 | LP5: 0 | LQ5: 0 | LR5: 0 | LS5: 0 | LT5: 0 | LU5: 0 | LV5: 0 | LW5: 0 | LX5: 0 | LY5: 0 | LZ5: 0 | MA5: 0 | MB5: 0 | MC5: 0 | MD5: 0 | ME5: 0 | MF5: 0 | MG5: 0 | MH5: 0 | MI5: 0 | MJ5: 0 | MK5: 0 | ML5: 0 | MM5: 0 | MN5: 0 | MO5: 0 | MP5: 0 | MQ5: 0 | MR5: 0 | MS5: 0 | MT5: 0 | MU5: 0 | MV5: 0 | MW5: 0 | MX5: 0 | MY5: 0 | MZ5: 0 | NA5: 0 | NB5: 0 | NC5: 0 | ND5: 0 | NE5: 0 | NF5: 0 | NG5: 0 | NH5: 0 | NI5: 0 | NJ5: 0 | NK5: 0 | NL5: 0 | NM5: 0 | NN5: 0 | NO5: 0 | NP5: 0 | NQ5: 0 | NR5: 0 | NS5: 0 | NT5: 0 | NU5: 0 | NV5: 0 | NW5: 0 | NX5: 0 | NY5: 0 | NZ5: 0 | OA5: 0 | OB5: 0 | OC5: 0 | OD5: 0 | OE5: 0 | OF5: 0 | OG5: 0 | OH5: 0 | OI5: 0 | OJ5: 0 | OK5: 0 | OL5: 10464.871 | OM5: 0 | ON5: 0 | OO5: 0.064376 | OP5: 0.431171 | OQ5: 20061.075
A6: 5 m_osd | B6: 0 | C6: 0 | D6: 0 | E6: 0 | F6: 0 | G6: 0 | H6: 0 | I6: 0 | J6: 0 | K6: 0 | L6: 0 | M6: 0 | N6: 0 | O6: 0 | P6: 0 | Q6: 0 | R6: 0 | S6: 0 | T6: 0 | U6: 0 | V6: 0 | W6: 0 | X6: 0 | Y6: 0 | Z6: 0 | AA6: 0 | AB6: 0 | AC6: 0 | AD6: 0 | AE6: 0 | AF6: 0 | AG6: 0 | AH6: 0 | AI6: 0 | AJ6: 0 | AK6: 0 | AL6: 0 | AM6: 0 | AN6: 0 | AO6: 0 | AP6: 0 | AQ6: 0 | AR6: 0 | AS6: 0 | AT6: 0 | AU6: 0 | AV6: 0 | AW6: 0 | AX6: 0 | AY6: 0 | AZ6: 0 | BA6: 0 | BB6: 0 | BC6: 0 | BD6: 0 | BE6: 0 | BF6: 0 | BG6: 0 | BH6: 0 | BI6: 0 | BJ6: 0 | BK6: 0 | BL6: 0 | BM6: 0 | BN6: 0 | BO6: 0 | BP6: 0 | BQ6: 0 | BR6: 0 | BS6: 0 | BT6: 0 | BU6: 0 | BV6: 0 | BW6: 0 | BX6: 0 | BY6: 0 | BZ6: 0 | CA6: 0 | CB6: 0 | CC6: 0 | CD6: 0 | CE6: 0 | CF6: 0 | CG6: 0 | CH6: 0 | CI6: 0 | CJ6: 0 | CK6: 0 | CL6: 0 | CM6: 0 | CN6: 0 | CO6: 0 | CP6: 0 | CQ6: 0 | CR6: 0 | CS6: 0 | CT6: 0 | CU6: 0 | CV6: 0 | CW6: 0 | CX6: 0 | CY6: 0 | CZ6: 0 | DA6: 0 | DB6: 0 | DC6: 0 | DD6: 0 | DE6: 0 | DF6: 0 | DG6: 0 | DH6: 0 | DI6: 0 | DJ6: 0 | DK6: 0 | DL6: 0 | DM6: 0 | DN6: 0 | DO6: 0 | DP6: 0 | DQ6: 0 | DR6: 0 | DS6: 0 | DT6: 0 | DU6: 0 | DV6: 0 | DW6: 0 | DX6: 0 | DY6: 0 | DZ6: 0 | EA6: 0 | EB6: 0 | EC6: 0 | ED6: 0 | EE6: 0 | EF6: 0 | EG6: 0 | EH6: 0 | EI6: 0 | EJ6: 0 | EK6: 0 | EL6: 0 | EM6: 0 | EN6: 0 | EO6: 0 | EP6: 0 | EQ6: 0 | ER6: 0 | ES6: 0 | ET6: 0 | EU6: 0 | EV6: 0 | EW6: 0 | EX6: 0.025701 | EY6: 0.102198 | EZ6: 0.525984 | FA6: 1.006569 | FB6: 174.45889 | FC6: 0.000671 | FD6: 0.014776 | FE6: 0.059039 | FF6: 9.549926 | FG6: 13.64735 | FH6: 5.91092 | FI6: 0.00745 | FJ6: 0.223592 | FK6: 0.005647 | FL6: 4e-06 | FM6: 0.030064 | FN6: 0.019238 | FO6: 0.000182 | FP6: 6.945862 | FQ6: 4.282421 | FR6: 1676.542 | FS6: 12.591805 | FT6: 0.175133 | FU6: 6.124818 | FV6: 252.40778 | FW6: 16.464819 | FX6: 2.325351 | FY6: 0.945673 | FZ6: 1.494475 | GA6: 0.297295 | GB6: 0.075287 | GC6: 0.002478 | GD6: 4.011809 | GE6: 0.047715 | GF6: 0.086443 | GG6: 0.030859 | GH6: 1.3e-05 | GI6: 0.000175 | GJ6: 0.011484 | GK6: 0.007351 | GL6: 0.003028 | GM6: 0.004963 | GN6: 0.000114 | GO6: 0.000132 | GP6: 0.076695 | GQ6: 0.000299 | GR6: 0.000196 | GS6: 0.00022 | GT6: 3.2e-05 | GU6: 4.6e-05 | GV6: 1.4e-05 | GW6: 0 | GX6: 1e-05 | GY6: 2.5e-05 | GZ6: 0 | HA6: 2e-05 | HB6: 3e-06 | HC6: 0.029329 | HD6: 0.006651 | HE6: 0.188247 | HF6: 0.535612 | HG6: 16.956064 | HH6: 0.014044 | HI6: 0.002546 | HJ6: 0.000647 | HK6: 0.014546 | HL6: 0.046524 | HM6: 0.093065 | HN6: 0.078328 | HO6: 0.033142 | HP6: 3.700973 | HQ6: 1.694964 | HR6: 23.277647 | HS6: 0.046419 | HT6: 1.609888 | HU6: 0.481892 | HV6: 0 | HW6: 0 | HX6: 0 | HY6: 0 | HZ6: 0 | IA6: 0 | IB6: 0 | IC6: 0 | ID6: 0 | IE6: 0 | IF6: 0 | IG6: 0 | IH6: 0 | II6: 0 | IJ6: 0 | IK6: 0 | IL6: 0 | IM6: 0 | IN6: 0 | IO6: 0 | IP6: 0 | IQ6: 0 | IR6: 0 | IS6: 0 | IT6: 0 | IU6: 0 | IV6: 0 | IW6: 0 | IX6: 0 | IY6: 0 | IZ6: 0 | JA6: 0 | JB6: 0 | JC6: 0 | JD6: 0 | JE6: 0 | JF6: 0 | JG6: 0 | JH6: 0 | JI6: 0 | JJ6: 0 | JK6: 0 | JL6: 0 | JM6: 0 | JN6: 0 | JO6: 0 | JP6: 0 | JQ6: 0 | JR6: 0 | JS6: 0 | JT6: 0 | JU6: 0 | JV6: 0 | JW6: 0 | JX6: 0 | JY6: 0 | JZ6: 0 | KA6: 0 | KB6: 0 | KC6: 0 | KD6: 0 | KE6: 0 | KF6: 0 | KG6: 0 | KH6: 0 | KI6: 0 | KJ6: 0 | KK6: 0 | KL6: 0 | KM6: 0 | KN6: 0 | KO6: 0 | KP6: 0 | KQ6: 0 | KR6: 0 | KS6: 0 | KT6: 0 | KU6: 0 | KV6: 0 | KW6: 0 | KX6: 0 | KY6: 0 | KZ6: 0 | LA6: 0 | LB6: 0 | LC6: 0 | LD6: 0 | LE6: 0 | LF6: 0 | LG6: 0 | LH6: 0 | LI6: 0 | LJ6: 0 | LK6: 0 | LL6: 0 | LM6: 0 | LN6: 0 | LO6: 0 | LP6: 0 | LQ6: 0 | LR6: 0 | LS6: 0 | LT6: 0 | LU6: 0 | LV6: 0 | LW6: 0 | LX6: 0 | LY6: 0 | LZ6: 0 | MA6: 0 | MB6: 0 | MC6: 0 | MD6: 0 | ME6: 0 | MF6: 0 | MG6: 0 | MH6: 0 | MI6: 0 | MJ6: 0 | MK6: 0 | ML6: 0 | MM6: 0 | MN6: 0 | MO6: 0 | MP6: 0 | MQ6: 0 | MR6: 0 | MS6: 0 | MT6: 0 | MU6: 0 | MV6: 0 | MW6: 0 | MX6: 0 | MY6: 0 | MZ6: 0 | NA6: 0 | NB6: 0 | NC6: 0 | ND6: 0 | NE6: 0 | NF6: 0 | NG6: 0 | NH6: 0 | NI6: 0 | NJ6: 0 | NK6: 0 | NL6: 0 | NM6: 0 | NN6: 0 | NO6: 0 | NP6: 0 | NQ6: 0 | NR6: 0 | NS6: 0 | NT6: 0 | NU6: 0 | NV6: 0 | NW6: 0 | NX6: 0 | NY6: 0 | NZ6: 0 | OA6: 0 | OB6: 0 | OC6: 0 | OD6: 0 | OE6: 0 | OF6: 0 | OG6: 0 | OH6: 0 | OI6: 0 | OJ6: 0 | OK6: 0 | OL6: 2.692938 | OM6: 0 | ON6: 0 | OO6: 9e-05 | OP6: 0.067752 | OQ6: 2242.1163
